Workbook

Sheet Thông tin
A1: Danh sách kịch bản kiểm thử chức năng ứng dụng di động
A3: Dự án | B3: Ứng dụng di động bán hàng
A4: Nền tảng | B4: ECAP — nền tảng cộng tác và phân tích dữ liệu cho doanh nghiệp vừa và nhỏ
A5: Đơn vị | B5: Công ty Demo SME (kinh doanh máy tính, linh kiện và phụ kiện)
A6: Người đọc | B6: Kiểm thử viên, trưởng nhóm phát triển
A7: Phiên bản | B7: 1.0
A8: Ngày phát hành | B8: 46321
A9: Phân loại | B9: Tài liệu nội bộ — Công ty Demo SME — dùng cho mục đích minh hoạ đồ án
A10: Số liệu | B10: Trạng thái kiểm thử là kết quả minh hoạ (số liệu minh hoạ).
A12: Chú giải
A13: Giá trị mẫu | B13: Ô nhập liệu (nền vàng, chữ xanh): người dùng được sửa hoặc nhập mới; mọi công thức tự tính lại.
A14: Công thức | B14: Ô công thức (nền trắng, chữ đen): tính tự động, không nhập đè.
A15: Tiêu đề | B15: Dòng tiêu đề bảng: đã cố định (freeze) và bật bộ lọc.
A17: Cấu trúc workbook
A18: Tổng hợp | B18: Số kịch bản theo phân hệ và trạng thái, tỷ lệ đạt và tiến độ tính bằng COUNTIFS; kết luận phát hành theo tiêu chí; biểu đồ.
A19: Kịch bản kiểm thử | B19: 46 kịch bản cho 11 phân hệ của ứng dụng di động ECAP (Flutter, Android). Cột Trạng thái là ô chọn.
A20: Danh sách | B20: Giá trị cho các ô chọn: trạng thái, mức ưu tiên.
A22: Giả định và nguồn dữ liệu
A23: 1. | B23: Kịch bản bám theo các màn hình có thật trong ứng dụng (ecap-mobile/lib/features): đăng nhập, quên/đặt lại mật khẩu, chấm công, nghỉ phép, công việc, tài liệu, thông báo, nhắn tin, hẹn lịch nghỉ qua chat, hồ sơ và kết nối (tự nhận địa chỉ Gateway từ cấu hình từ xa).
A24: 2. | B24: Thông điệp mong đợi trích từ giao diện ứng dụng; các chức năng ngoài phạm vi mobile (CRM, báo cáo, quản trị, duyệt nghỉ phép) chỉ được kiểm tra là không xuất hiện.
A25: 3. | B25: Trạng thái, ngày kiểm thử và người kiểm thử là kết quả một lần chạy minh hoạ — cập nhật khi chạy thật.
A26: 4. | B26: Đã chạy = Đạt + Không đạt (kịch bản Bị chặn chưa thực hiện được nên không tính). Tỷ lệ đạt = Đạt / Đã chạy. Tiến độ = Đã chạy / Tổng.
A27: 5. | B27: Tiêu chí phát hành (giả định minh hoạ, sửa ở sheet Tổng hợp): tỷ lệ đạt ≥ 95% và không có kịch bản ưu tiên Cao bị Không đạt.
A28: 6. | B28: Không ghi mật khẩu trong tài liệu; dùng tài khoản demo theo hướng dẫn nội bộ của dự án.

Sheet Tổng hợp
A1: Tổng hợp kết quả kiểm thử
A2: Mọi ô số là công thức COUNTIFS từ sheet Kịch bản kiểm thử; số liệu minh hoạ.
A3: 1. Theo phân hệ
A4: Phân hệ | B4: Tổng kịch bản | C4: Đạt | D4: Không đạt | E4: Bị chặn | F4: Chưa chạy | G4: Đã chạy | H4: Tỷ lệ đạt | I4: Tiến độ thực hiện
A5: Đăng nhập | B5: =COUNTIFS('Kịch bản kiểm thử'!$B$5:$B$300,A5) -> 4 | C5: =COUNTIFS('Kịch bản kiểm thử'!$B$5:$B$300,$A5,'Kịch bản kiểm thử'!$K$5:$K$300,C$4) -> 4 | D5: =COUNTIFS('Kịch bản kiểm thử'!$B$5:$B$300,$A5,'Kịch bản kiểm thử'!$K$5:$K$300,D$4) -> 0 | E5: =COUNTIFS('Kịch bản kiểm thử'!$B$5:$B$300,$A5,'Kịch bản kiểm thử'!$K$5:$K$300,E$4) -> 0 | F5: =COUNTIFS('Kịch bản kiểm thử'!$B$5:$B$300,$A5,'Kịch bản kiểm thử'!$K$5:$K$300,F$4) -> 0 | G5: =C5+D5 -> 4 | H5: =IFERROR(C5/G5,0) -> 1 | I5: =IFERROR(G5/B5,0) -> 1
A6: Quên/Đặt lại mật khẩu | B6: =COUNTIFS('Kịch bản kiểm thử'!$B$5:$B$300,A6) -> 5 | C6: =COUNTIFS('Kịch bản kiểm thử'!$B$5:$B$300,$A6,'Kịch bản kiểm thử'!$K$5:$K$300,C$4) -> 5 | D6: =COUNTIFS('Kịch bản kiểm thử'!$B$5:$B$300,$A6,'Kịch bản kiểm thử'!$K$5:$K$300,D$4) -> 0 | E6: =COUNTIFS('Kịch bản kiểm thử'!$B$5:$B$300,$A6,'Kịch bản kiểm thử'!$K$5:$K$300,E$4) -> 0 | F6: =COUNTIFS('Kịch bản kiểm thử'!$B$5:$B$300,$A6,'Kịch bản kiểm thử'!$K$5:$K$300,F$4) -> 0 | G6: =C6+D6 -> 5 | H6: =IFERROR(C6/G6,0) -> 1 | I6: =IFERROR(G6/B6,0) -> 1
A7: Chấm công | B7: =COUNTIFS('Kịch bản kiểm thử'!$B$5:$B$300,A7) -> 6 | C7: =COUNTIFS('Kịch bản kiểm thử'!$B$5:$B$300,$A7,'Kịch bản kiểm thử'!$K$5:$K$300,C$4) -> 5 | D7: =COUNTIFS('Kịch bản kiểm thử'!$B$5:$B$300,$A7,'Kịch bản kiểm thử'!$K$5:$K$300,D$4) -> 0 | E7: =COUNTIFS('Kịch bản kiểm thử'!$B$5:$B$300,$A7,'Kịch bản kiểm thử'!$K$5:$K$300,E$4) -> 0 | F7: =COUNTIFS('Kịch bản kiểm thử'!$B$5:$B$300,$A7,'Kịch bản kiểm thử'!$K$5:$K$300,F$4) -> 1 | G7: =C7+D7 -> 5 | H7: =IFERROR(C7/G7,0) -> 1 | I7: =IFERROR(G7/B7,0) -> 0.83333333
A8: Nghỉ phép | B8: =COUNTIFS('Kịch bản kiểm thử'!$B$5:$B$300,A8) -> 5 | C8: =COUNTIFS('Kịch bản kiểm thử'!$B$5:$B$300,$A8,'Kịch bản kiểm thử'!$K$5:$K$300,C$4) -> 4 | D8: =COUNTIFS('Kịch bản kiểm thử'!$B$5:$B$300,$A8,'Kịch bản kiểm thử'!$K$5:$K$300,D$4) -> 0 | E8: =COUNTIFS('Kịch bản kiểm thử'!$B$5:$B$300,$A8,'Kịch bản kiểm thử'!$K$5:$K$300,E$4) -> 1 | F8: =COUNTIFS('Kịch bản kiểm thử'!$B$5:$B$300,$A8,'Kịch bản kiểm thử'!$K$5:$K$300,F$4) -> 0 | G8: =C8+D8 -> 4 | H8: =IFERROR(C8/G8,0) -> 1 | I8: =IFERROR(G8/B8,0) -> 0.8
A9: Công việc | B9: =COUNTIFS('Kịch bản kiểm thử'!$B$5:$B$300,A9) -> 5 | C9: =COUNTIFS('Kịch bản kiểm thử'!$B$5:$B$300,$A9,'Kịch bản kiểm thử'!$K$5:$K$300,C$4) -> 5 | D9: =COUNTIFS('Kịch bản kiểm thử'!$B$5:$B$300,$A9,'Kịch bản kiểm thử'!$K$5:$K$300,D$4) -> 0 | E9: =COUNTIFS('Kịch bản kiểm thử'!$B$5:$B$300,$A9,'Kịch bản kiểm thử'!$K$5:$K$300,E$4) -> 0 | F9: =COUNTIFS('Kịch bản kiểm thử'!$B$5:$B$300,$A9,'Kịch bản kiểm thử'!$K$5:$K$300,F$4) -> 0 | G9: =C9+D9 -> 5 | H9: =IFERROR(C9/G9,0) -> 1 | I9: =IFERROR(G9/B9,0) -> 1
A10: Tài liệu | B10: =COUNTIFS('Kịch bản kiểm thử'!$B$5:$B$300,A10) -> 5 | C10: =COUNTIFS('Kịch bản kiểm thử'!$B$5:$B$300,$A10,'Kịch bản kiểm thử'!$K$5:$K$300,C$4) -> 5 | D10: =COUNTIFS('Kịch bản kiểm thử'!$B$5:$B$300,$A10,'Kịch bản kiểm thử'!$K$5:$K$300,D$4) -> 0 | E10: =COUNTIFS('Kịch bản kiểm thử'!$B$5:$B$300,$A10,'Kịch bản kiểm thử'!$K$5:$K$300,E$4) -> 0 | F10: =COUNTIFS('Kịch bản kiểm thử'!$B$5:$B$300,$A10,'Kịch bản kiểm thử'!$K$5:$K$300,F$4) -> 0 | G10: =C10+D10 -> 5 | H10: =IFERROR(C10/G10,0) -> 1 | I10: =IFERROR(G10/B10,0) -> 1
A11: Thông báo | B11: =COUNTIFS('Kịch bản kiểm thử'!$B$5:$B$300,A11) -> 3 | C11: =COUNTIFS('Kịch bản kiểm thử'!$B$5:$B$300,$A11,'Kịch bản kiểm thử'!$K$5:$K$300,C$4) -> 3 | D11: =COUNTIFS('Kịch bản kiểm thử'!$B$5:$B$300,$A11,'Kịch bản kiểm thử'!$K$5:$K$300,D$4) -> 0 | E11: =COUNTIFS('Kịch bản kiểm thử'!$B$5:$B$300,$A11,'Kịch bản kiểm thử'!$K$5:$K$300,E$4) -> 0 | F11: =COUNTIFS('Kịch bản kiểm thử'!$B$5:$B$300,$A11,'Kịch bản kiểm thử'!$K$5:$K$300,F$4) -> 0 | G11: =C11+D11 -> 3 | H11: =IFERROR(C11/G11,0) -> 1 | I11: =IFERROR(G11/B11,0) -> 1
A12: Nhắn tin | B12: =COUNTIFS('Kịch bản kiểm thử'!$B$5:$B$300,A12) -> 5 | C12: =COUNTIFS('Kịch bản kiểm thử'!$B$5:$B$300,$A12,'Kịch bản kiểm thử'!$K$5:$K$300,C$4) -> 4 | D12: =COUNTIFS('Kịch bản kiểm thử'!$B$5:$B$300,$A12,'Kịch bản kiểm thử'!$K$5:$K$300,D$4) -> 0 | E12: =COUNTIFS('Kịch bản kiểm thử'!$B$5:$B$300,$A12,'Kịch bản kiểm thử'!$K$5:$K$300,E$4) -> 0 | F12: =COUNTIFS('Kịch bản kiểm thử'!$B$5:$B$300,$A12,'Kịch bản kiểm thử'!$K$5:$K$300,F$4) -> 1 | G12: =C12+D12 -> 4 | H12: =IFERROR(C12/G12,0) -> 1 | I12: =IFERROR(G12/B12,0) -> 0.8
A13: Hẹn lịch nghỉ | B13: =COUNTIFS('Kịch bản kiểm thử'!$B$5:$B$300,A13) -> 5 | C13: =COUNTIFS('Kịch bản kiểm thử'!$B$5:$B$300,$A13,'Kịch bản kiểm thử'!$K$5:$K$300,C$4) -> 4 | D13: =COUNTIFS('Kịch bản kiểm thử'!$B$5:$B$300,$A13,'Kịch bản kiểm thử'!$K$5:$K$300,D$4) -> 1 | E13: =COUNTIFS('Kịch bản kiểm thử'!$B$5:$B$300,$A13,'Kịch bản kiểm thử'!$K$5:$K$300,E$4) -> 0 | F13: =COUNTIFS('Kịch bản kiểm thử'!$B$5:$B$300,$A13,'Kịch bản kiểm thử'!$K$5:$K$300,F$4) -> 0 | G13: =C13+D13 -> 5 | H13: =IFERROR(C13/G13,0) -> 0.8 | I13: =IFERROR(G13/B13,0) -> 1
A14: Hồ sơ | B14: =COUNTIFS('Kịch bản kiểm thử'!$B$5:$B$300,A14) -> 2 | C14: =COUNTIFS('Kịch bản kiểm thử'!$B$5:$B$300,$A14,'Kịch bản kiểm thử'!$K$5:$K$300,C$4) -> 2 | D14: =COUNTIFS('Kịch bản kiểm thử'!$B$5:$B$300,$A14,'Kịch bản kiểm thử'!$K$5:$K$300,D$4) -> 0 | E14: =COUNTIFS('Kịch bản kiểm thử'!$B$5:$B$300,$A14,'Kịch bản kiểm thử'!$K$5:$K$300,E$4) -> 0 | F14: =COUNTIFS('Kịch bản kiểm thử'!$B$5:$B$300,$A14,'Kịch bản kiểm thử'!$K$5:$K$300,F$4) -> 0 | G14: =C14+D14 -> 2 | H14: =IFERROR(C14/G14,0) -> 1 | I14: =IFERROR(G14/B14,0) -> 1
A15: Kết nối | B15: =COUNTIFS('Kịch bản kiểm thử'!$B$5:$B$300,A15) -> 1 | C15: =COUNTIFS('Kịch bản kiểm thử'!$B$5:$B$300,$A15,'Kịch bản kiểm thử'!$K$5:$K$300,C$4) -> 0 | D15: =COUNTIFS('Kịch bản kiểm thử'!$B$5:$B$300,$A15,'Kịch bản kiểm thử'!$K$5:$K$300,D$4) -> 0 | E15: =COUNTIFS('Kịch bản kiểm thử'!$B$5:$B$300,$A15,'Kịch bản kiểm thử'!$K$5:$K$300,E$4) -> 0 | F15: =COUNTIFS('Kịch bản kiểm thử'!$B$5:$B$300,$A15,'Kịch bản kiểm thử'!$K$5:$K$300,F$4) -> 1 | G15: =C15+D15 -> 0 | H15: =IFERROR(C15/G15,0) -> 0 | I15: =IFERROR(G15/B15,0) -> 0
A16: Tổng cộng | B16: =SUM(B5:B15) -> 46 | C16: =SUM(C5:C15) -> 41 | D16: =SUM(D5:D15) -> 1 | E16: =SUM(E5:E15) -> 1 | F16: =SUM(F5:F15) -> 3 | G16: =SUM(G5:G15) -> 42 | H16: =IFERROR(C16/G16,0) -> 0.97619048 | I16: =IFERROR(G16/B16,0) -> 0.91304348
A17: Kiểm tra | B17: =IF(B16=COUNTA('Kịch bản kiểm thử'!$A$5:$A$300),"Khớp số kịch bản","Lệch — kiểm tra cột Phân hệ") -> Khớp số kịch bản
A19: 2. Theo mức ưu tiên
A20: Mức ưu tiên | B20: Tổng kịch bản | C20: Đạt | D20: Không đạt | E20: Bị chặn | F20: Chưa chạy | G20: Đã chạy | H20: Tỷ lệ đạt | I20: Tiến độ thực hiện
A21: Cao | B21: =COUNTIFS('Kịch bản kiểm thử'!$J$5:$J$300,A21) -> 18 | C21: =COUNTIFS('Kịch bản kiểm thử'!$J$5:$J$300,$A21,'Kịch bản kiểm thử'!$K$5:$K$300,"Đạt") -> 18 | D21: =COUNTIFS('Kịch bản kiểm thử'!$J$5:$J$300,$A21,'Kịch bản kiểm thử'!$K$5:$K$300,"Không đạt") -> 0 | E21: =COUNTIFS('Kịch bản kiểm thử'!$J$5:$J$300,$A21,'Kịch bản kiểm thử'!$K$5:$K$300,"Bị chặn") -> 0 | F21: =COUNTIFS('Kịch bản kiểm thử'!$J$5:$J$300,$A21,'Kịch bản kiểm thử'!$K$5:$K$300,"Chưa chạy") -> 0 | G21: =C21+D21 -> 18 | H21: =IFERROR(C21/G21,0) -> 1 | I21: =IFERROR(G21/B21,0) -> 1
A22: Trung bình | B22: =COUNTIFS('Kịch bản kiểm thử'!$J$5:$J$300,A22) -> 19 | C22: =COUNTIFS('Kịch bản kiểm thử'!$J$5:$J$300,$A22,'Kịch bản kiểm thử'!$K$5:$K$300,"Đạt") -> 16 | D22: =COUNTIFS('Kịch bản kiểm thử'!$J$5:$J$300,$A22,'Kịch bản kiểm thử'!$K$5:$K$300,"Không đạt") -> 0 | E22: =COUNTIFS('Kịch bản kiểm thử'!$J$5:$J$300,$A22,'Kịch bản kiểm thử'!$K$5:$K$300,"Bị chặn") -> 1 | F22: =COUNTIFS('Kịch bản kiểm thử'!$J$5:$J$300,$A22,'Kịch bản kiểm thử'!$K$5:$K$300,"Chưa chạy") -> 2 | G22: =C22+D22 -> 16 | H22: =IFERROR(C22/G22,0) -> 1 | I22: =IFERROR(G22/B22,0) -> 0.84210526
A23: Thấp | B23: =COUNTIFS('Kịch bản kiểm thử'!$J$5:$J$300,A23) -> 9 | C23: =COUNTIFS('Kịch bản kiểm thử'!$J$5:$J$300,$A23,'Kịch bản kiểm thử'!$K$5:$K$300,"Đạt") -> 7 | D23: =COUNTIFS('Kịch bản kiểm thử'!$J$5:$J$300,$A23,'Kịch bản kiểm thử'!$K$5:$K$300,"Không đạt") -> 1 | E23: =COUNTIFS('Kịch bản kiểm thử'!$J$5:$J$300,$A23,'Kịch bản kiểm thử'!$K$5:$K$300,"Bị chặn") -> 0 | F23: =COUNTIFS('Kịch bản kiểm thử'!$J$5:$J$300,$A23,'Kịch bản kiểm thử'!$K$5:$K$300,"Chưa chạy") -> 1 | G23: =C23+D23 -> 8 | H23: =IFERROR(C23/G23,0) -> 0.875 | I23: =IFERROR(G23/B23,0) -> 0.88888889
A25: 3. Kết luận phát hành
A26: Chỉ tiêu | B26: Giá trị | C26: Ghi chú
A27: Ngưỡng tỷ lệ đạt tối thiểu | B27: 0.95 | C27: Ô nhập liệu — tiêu chí giả định minh hoạ
A28: Tỷ lệ đạt hiện tại | B28: =H16 -> 0.97619048 | C28: Đạt / (Đạt + Không đạt)
A29: Tiến độ thực hiện | B29: =I16 -> 0.91304348 | C29: Đã chạy / Tổng
A30: Số kịch bản ưu tiên Cao bị Không đạt | B30: =D21 -> 0 | C30: Phải bằng 0
A31: Số kịch bản chưa chạy hoặc bị chặn | B31: =E16+F16 -> 4 | C31: Cần xử lý trước khi chốt
A32: Kết luận | B32: =IF(AND(B28>=B27,B30=0,B31=0),"Đủ điều kiện phát hành",IF(AND(B28>=B27,B30=0),"Đạt tiêu chí, còn kịch bản chưa chạy hoặc bị chặn","Chưa đủ điều kiện phát hành")) -> Đạt tiêu chí, còn kịch bản chưa chạy hoặc bị chặn

Sheet Kịch bản kiểm thử
A1: Kịch bản kiểm thử chức năng — ứng dụng di động ECAP
A2: Cột Trạng thái, Ngày kiểm thử, Người kiểm thử, Ghi chú là ô nhập liệu.
A4: Mã TC | B4: Phân hệ | C4: Màn hình | D4: Tiêu đề kịch bản | E4: Điều kiện tiên quyết | F4: Các bước thực hiện | G4: Dữ liệu kiểm thử | H4: Kết quả mong đợi | I4: Vai trò | J4: Mức ưu tiên | K4: Trạng thái | L4: Ngày kiểm thử | M4: Người kiểm thử | N4: Ghi chú
A5: TC-01 | B5: Đăng nhập | C5: LoginPage | D5: Đăng nhập thành công bằng tài khoản Employee | E5: Ứng dụng đã cài, có kết nối tới Gateway | F5: 1. Mở ứng dụng 2. Nhập email và mật khẩu 3. Bấm "Đăng nhập" | G5: Tài khoản Employee demo (an.nguyen+141603@demo-sme.vn) | H5: Vào màn hình chính với 7 tab: Chấm công, Nghỉ phép, Công việc, Tài liệu, Thông báo, Nhắn tin, Hồ sơ | I5: Employee | J5: Cao | K5: Đạt | L5: 46318 | M5: Nhóm kiểm thử
A6: TC-02 | B6: Đăng nhập | C6: LoginPage | D6: Đăng nhập sai mật khẩu | E6: Ứng dụng đã cài | F6: 1. Nhập email đúng, mật khẩu sai 2. Bấm "Đăng nhập" | G6: Mật khẩu sai bất kỳ | H6: Hiện thông báo lỗi, vẫn ở màn hình đăng nhập, không lưu phiên | I6: Employee | J6: Cao | K6: Đạt | L6: 46318 | M6: Nhóm kiểm thử
A7: TC-03 | B7: Đăng nhập | C7: LoginPage | D7: Tự động đăng nhập lại khi mở lại ứng dụng | E7: Đã đăng nhập trước đó, chưa đăng xuất | F7: 1. Đóng hẳn ứng dụng 2. Mở lại | G7: — | H7: Vào thẳng màn hình chính nhờ làm mới token (POST /auth/refresh), không phải nhập lại mật khẩu | I7: Employee | J7: Trung bình | K7: Đạt | L7: 46318 | M7: Nhóm kiểm thử
A8: TC-04 | B8: Đăng nhập | C8: LoginPage | D8: Hiển thị thông tin màn hình đăng nhập | E8: Chưa đăng nhập | F8: 1. Mở ứng dụng 2. Quan sát màn hình | G8: — | H8: Có dòng mô tả "Chấm công · Nghỉ phép · Công việc · Tài liệu" và liên kết "Quên mật khẩu?" | I8: Employee | J8: Thấp | K8: Đạt | L8: 46318 | M8: Nhóm kiểm thử
A9: TC-05 | B9: Quên/Đặt lại mật khẩu | C9: ForgotPasswordPage | D9: Gửi liên kết khi để trống email | E9: Đang ở màn hình Quên mật khẩu | F9: 1. Để trống ô email 2. Bấm "Gửi liên kết" | G9: Email rỗng | H9: Hiện "Vui lòng nhập email", không gọi API | I9: Employee | J9: Trung bình | K9: Đạt | L9: 46318 | M9: Nhóm kiểm thử
A10: TC-06 | B10: Quên/Đặt lại mật khẩu | C10: ForgotPasswordPage | D10: Gửi liên kết đặt lại mật khẩu | E10: Đang ở màn hình Quên mật khẩu | F10: 1. Nhập email đăng nhập 2. Bấm "Gửi liên kết" | G10: Tài khoản Employee demo (an.nguyen+141603@demo-sme.vn) | H10: Hiện thông báo: nếu email tồn tại trong hệ thống, một liên kết đặt lại mật khẩu đã được gửi tới hộp thư | I10: Employee | J10: Trung bình | K10: Đạt | L10: 46318 | M10: Nhóm kiểm thử
A11: TC-07 | B11: Quên/Đặt lại mật khẩu | C11: ResetPasswordPage | D11: Mật khẩu mới ngắn hơn 8 ký tự | E11: Đã có mã đặt lại mật khẩu (token) | F11: 1. Dán token 2. Nhập mật khẩu mới 6 ký tự 3. Bấm "Đặt lại mật khẩu" | G11: Mật khẩu 6 ký tự | H11: Hiện "Mật khẩu mới phải có ít nhất 8 ký tự" | I11: Employee | J11: Trung bình | K11: Đạt | L11: 46318 | M11: Nhóm kiểm thử
A12: TC-08 | B12: Quên/Đặt lại mật khẩu | C12: ResetPasswordPage | D12: Xác nhận mật khẩu không khớp | E12: Đã có token | F12: 1. Nhập mật khẩu mới và xác nhận khác nhau 2. Bấm "Đặt lại mật khẩu" | G12: Hai mật khẩu khác nhau | H12: Hiện "Xác nhận mật khẩu không khớp" | I12: Employee | J12: Trung bình | K12: Đạt | L12: 46318 | M12: Nhóm kiểm thử
A13: TC-09 | B13: Quên/Đặt lại mật khẩu | C13: ResetPasswordPage | D13: Đặt lại mật khẩu thành công bằng token dán tay | E13: Đã nhận email đặt lại, sao chép phần sau "?token=" | F13: 1. Bấm "Đã có mã đặt lại mật khẩu? Nhập tại đây" 2. Dán token, nhập mật khẩu mới hợp lệ hai lần 3. Bấm "Đặt lại mật khẩu" | G13: Token hợp lệ, mật khẩu ≥ 8 ký tự | H13: Hiện "Đặt lại mật khẩu thành công. Hãy đăng nhập lại bằng mật khẩu mới." và nút "Về trang đăng nhập" | I13: Employee | J13: Cao | K13: Đạt | L13: 46318 | M13: Nhóm kiểm thử | N13: Ứng dụng chưa xử lý deep-link, token dán tay là thiết kế có chủ đích
A14: TC-10 | B14: Chấm công | C14: AttendancePage | D14: Chấm công vào làm kèm ảnh | E14: Đã đăng nhập bằng tài khoản Employee demo, đã cấp quyền camera, chưa chấm công hôm nay | F14: 1. Mở tab Chấm công 2. Bấm "Vào làm" 3. Chụp ảnh và xác nhận | G14: Ảnh chụp bằng camera thật | H14: Hiện "Chấm công vào làm thành công"; khối "Hôm nay" hiện "Vào làm lúc: ..." | I14: Employee | J14: Cao | K14: Đạt | L14: 46318 | M14: Nhóm kiểm thử
A15: TC-11 | B15: Chấm công | C15: AttendancePage | D15: Chấm công ra về kèm ảnh | E15: Đã chấm công vào làm hôm nay | F15: 1. Bấm "Ra về" 2. Chụp ảnh và xác nhận | G15: Ảnh chụp bằng camera thật | H15: Hiện "Chấm công ra về thành công"; khối "Hôm nay" hiện "Ra về lúc: ..." | I15: Employee | J15: Cao | K15: Đạt | L15: 46318 | M15: Nhóm kiểm thử
A16: TC-12 | B16: Chấm công | C16: AttendancePage | D16: Từ chối quyền camera | E16: Quyền camera của ứng dụng bị tắt | F16: 1. Bấm "Vào làm" | G16: — | H16: Hiện "Không thể truy cập camera, vui lòng kiểm tra quyền truy cập"; ứng dụng không bị thoát | I16: Employee | J16: Cao | K16: Đạt | L16: 46318 | M16: Nhóm kiểm thử
A17: TC-13 | B17: Chấm công | C17: AttendancePage | D17: Chấm công khi tắt dịch vụ vị trí | E17: Tắt GPS hoặc từ chối quyền vị trí | F17: 1. Bấm "Vào làm" 2. Chụp ảnh và xác nhận | G17: — | H17: Vẫn chấm công thành công (vị trí là tín hiệu mềm, không chặn check-in/out); không hiện cờ vị trí | I17: Employee | J17: Trung bình | K17: Đạt | L17: 46318 | M17: Nhóm kiểm thử
A18: TC-14 | B18: Chấm công | C18: AttendancePage | D18: Hiển thị cờ vị trí "Tại văn phòng"/"Ngoài văn phòng" | E18: Bật GPS, đã cấp quyền vị trí | F18: 1. Chấm công tại văn phòng 2. Chấm công ở vị trí khác (ngày khác) | G18: Hai vị trí khác nhau | H18: Bản ghi hiện đúng "Tại văn phòng" hoặc "Ngoài văn phòng" ở khối Hôm nay và Lịch sử chấm công | I18: Employee | J18: Trung bình | K18: Chưa chạy | N18: Cần chạy tại văn phòng thật
A19: TC-15 | B19: Chấm công | C19: AttendancePage | D19: Xem lịch sử chấm công | E19: Đã đăng nhập bằng tài khoản Employee demo | F19: 1. Mở tab Chấm công 2. Cuộn xuống "Lịch sử chấm công" | G19: — | H19: Mỗi dòng hiện "Vào: ... · Ra: ..."; tài khoản mới hiện "Chưa có bản ghi chấm công nào" | I19: Employee | J19: Thấp | K19: Đạt | L19: 46318 | M19: Nhóm kiểm thử
A20: TC-16 | B20: Nghỉ phép | C20: LeaveRequestsPage | D20: Tạo yêu cầu nghỉ phép hợp lệ | E20: Đã đăng nhập bằng tài khoản Employee demo | F20: 1. Mở tab Nghỉ phép 2. Bấm "Tạo yêu cầu" 3. Chọn ngày bắt đầu, ngày kết thúc, nhập lý do 4. Bấm "Gửi" | G20: 2 ngày liên tiếp, lý do "Việc gia đình" | H20: Yêu cầu mới xuất hiện trong danh sách với trạng thái "Chờ duyệt" và khoảng ngày "dd/mm/yyyy → dd/mm/yyyy" | I20: Employee | J20: Cao | K20: Đạt | L20: 46318 | M20: Nhóm kiểm thử
A21: TC-17 | B21: Nghỉ phép | C21: LeaveRequestsPage | D21: Thiếu lý do khi tạo yêu cầu | E21: Đang mở hộp thoại Tạo yêu cầu nghỉ phép | F21: 1. Chọn ngày, để trống lý do 2. Bấm "Gửi" | G21: Lý do rỗng | H21: Hiện "Vui lòng nhập đầy đủ ngày bắt đầu, ngày kết thúc và lý do" | I21: Employee | J21: Trung bình | K21: Đạt | L21: 46319 | M21: Nhóm kiểm thử
A22: TC-18 | B22: Nghỉ phép | C22: LeaveRequestsPage | D22: Ngày kết thúc trước ngày bắt đầu | E22: Đang mở hộp thoại Tạo yêu cầu nghỉ phép | F22: 1. Chọn ngày kết thúc sớm hơn ngày bắt đầu 2. Bấm "Gửi" | G22: Bắt đầu 30/10, kết thúc 29/10 | H22: Hiện "Ngày kết thúc phải sau hoặc bằng ngày bắt đầu" | I22: Employee | J22: Trung bình | K22: Đạt | L22: 46319 | M22: Nhóm kiểm thử
A23: TC-19 | B23: Nghỉ phép | C23: LeaveRequestsPage | D23: Cập nhật trạng thái sau khi được duyệt trên web | E23: Có yêu cầu "Chờ duyệt"; Manager duyệt hoặc từ chối trên web | F23: 1. Manager duyệt yêu cầu trên web 2. Trên điện thoại, kéo để làm mới danh sách | G23: — | H23: Trạng thái đổi thành "Đã duyệt" hoặc "Đã từ chối" | I23: Employee + Manager (web) | J23: Trung bình | K23: Bị chặn | L23: 46319 | M23: Nhóm kiểm thử | N23: Chờ tài khoản Manager duyệt đơn trên web
A24: TC-20 | B24: Nghỉ phép | C24: LeaveRequestsPage | D24: Không có chức năng duyệt nghỉ phép trên mobile | E24: Đã đăng nhập bằng tài khoản Employee demo | F24: 1. Mở tab Nghỉ phép 2. Quan sát các nút thao tác | G24: — | H24: Chỉ có tạo và xem yêu cầu của chính mình; không có nút duyệt/từ chối (thuộc web) | I24: Employee | J24: Thấp | K24: Đạt | L24: 46319 | M24: Nhóm kiểm thử | N24: Kiểm tra phạm vi
A25: TC-21 | B25: Công việc | C25: TasksPage | D25: Chỉ hiện công việc được giao cho mình | E25: Tài khoản được giao ít nhất 1 công việc ở một dự án | F25: 1. Mở tab Công việc | G25: — | H25: Danh sách chỉ gồm công việc có mình là người phụ trách, mỗi dòng kèm tên dự án | I25: Employee | J25: Cao | K25: Đạt | L25: 46319 | M25: Nhóm kiểm thử
A26: TC-22 | B26: Công việc | C26: TasksPage | D26: Chuyển Cần làm → Đang làm | E26: Có công việc trạng thái "Cần làm" | F26: 1. Mở menu trạng thái của công việc 2. Chọn "Chuyển sang: Đang làm" | G26: — | H26: Menu chỉ có bước hợp lệ "Đang làm"; trạng thái cập nhật ngay sau khi chọn | I26: Employee | J26: Cao | K26: Đạt | L26: 46319 | M26: Nhóm kiểm thử
A27: TC-23 | B27: Công việc | C27: TasksPage | D27: Chuyển Đang làm → Hoàn thành | E27: Có công việc trạng thái "Đang làm" | F27: 1. Mở menu trạng thái 2. Chọn "Chuyển sang: Hoàn thành" | G27: — | H27: Menu hiện "Cần làm" và "Hoàn thành"; chọn Hoàn thành thì trạng thái cập nhật | I27: Employee | J27: Cao | K27: Đạt | L27: 46319 | M27: Nhóm kiểm thử
A28: TC-24 | B28: Công việc | C28: TasksPage | D28: Tài khoản chưa được giao việc | E28: Tài khoản không có công việc nào | F28: 1. Mở tab Công việc | G28: — | H28: Hiện "Bạn chưa được giao công việc nào" | I28: Employee | J28: Thấp | K28: Đạt | L28: 46319 | M28: Nhóm kiểm thử
A29: TC-25 | B29: Công việc | C29: TasksPage | D29: Không có tạo/xoá công việc và Kanban | E29: Đã đăng nhập bằng tài khoản Employee demo | F29: 1. Mở tab Công việc 2. Quan sát thao tác có sẵn | G29: — | H29: Không có nút tạo/xoá công việc, không có bảng Kanban kéo-thả | I29: Employee | J29: Thấp | K29: Đạt | L29: 46319 | M29: Nhóm kiểm thử | N29: Kiểm tra phạm vi
A30: TC-26 | B30: Tài liệu | C30: DocumentsPage | D30: Duyệt cây thư mục | E30: Tổ chức có thư mục và file mẫu | F30: 1. Mở tab Tài liệu 2. Mở một thư mục con 3. Quay lại thư mục cha | G30: — | H30: Hiện đúng thư mục con và file của từng cấp; quay lại đúng cấp trước | I30: Employee | J30: Cao | K30: Đạt | L30: 46319 | M30: Nhóm kiểm thử
A31: TC-27 | B31: Tài liệu | C31: DocumentsPage | D31: Mở file PDF | E31: Thư mục có file PDF | F31: 1. Bấm vào file PDF | G31: File PDF mẫu | H31: File mở bằng trình duyệt hoặc trình xem PDF mặc định của điện thoại | I31: Employee | J31: Cao | K31: Đạt | L31: 46319 | M31: Nhóm kiểm thử
A32: TC-28 | B32: Tài liệu | C32: DocumentsPage | D32: Tải file lên thư mục hiện tại | E32: Đang ở một thư mục | F32: 1. Bấm nút tải lên 2. Chọn một file trong bộ nhớ máy | G32: File ảnh hoặc PDF dưới 10 MB | H32: File mới xuất hiện trong danh sách của thư mục | I32: Employee | J32: Cao | K32: Đạt | L32: 46319 | M32: Nhóm kiểm thử
A33: TC-29 | B33: Tài liệu | C33: DocumentsPage | D33: Huỷ chọn file khi tải lên | E33: Đang ở một thư mục | F33: 1. Bấm nút tải lên 2. Đóng trình chọn file mà không chọn | G33: — | H33: Không có lỗi, ứng dụng không bị thoát, danh sách giữ nguyên | I33: Employee | J33: Trung bình | K33: Đạt | L33: 46319 | M33: Nhóm kiểm thử | N33: Hồi quy lỗi danh sách file rỗng đã sửa
A34: TC-30 | B34: Tài liệu | C34: DocumentsPage | D34: Thư mục trống | E34: Có thư mục không chứa gì | F34: 1. Mở thư mục trống | G34: — | H34: Hiện "Thư mục này chưa có nội dung nào" | I34: Employee | J34: Thấp | K34: Đạt | L34: 46319 | M34: Nhóm kiểm thử
A35: TC-31 | B35: Thông báo | C35: NotificationsPage | D35: Xem và làm mới danh sách thông báo | E35: Đã đăng nhập bằng tài khoản Employee demo | F35: 1. Mở tab Thông báo 2. Kéo xuống để làm mới | G35: — | H35: Hiện danh sách thông báo mới nhất; tài khoản chưa có thì hiện "Chưa có thông báo nào" | I35: Employee | J35: Trung bình | K35: Đạt | L35: 46319 | M35: Nhóm kiểm thử
A36: TC-32 | B36: Thông báo | C36: NotificationsPage | D36: Đánh dấu một thông báo đã đọc | E36: Có thông báo chưa đọc | F36: 1. Bấm vào một thông báo chưa đọc | G36: — | H36: Thông báo chuyển sang trạng thái đã đọc | I36: Employee | J36: Trung bình | K36: Đạt | L36: 46321 | M36: Nhóm kiểm thử
A37: TC-33 | B37: Thông báo | C37: NotificationsPage | D37: Đánh dấu tất cả đã đọc | E37: Có nhiều thông báo chưa đọc | F37: 1. Bấm "Đánh dấu tất cả đã đọc" | G37: — | H37: Mọi thông báo chuyển sang đã đọc | I37: Employee | J37: Trung bình | K37: Đạt | L37: 46321 | M37: Nhóm kiểm thử
A38: TC-34 | B38: Nhắn tin | C38: ConversationsPage | D38: Tạo hội thoại 1:1 | E38: Tổ chức có ít nhất 2 thành viên | F38: 1. Mở tab Nhắn tin 2. Tạo "Cuộc trò chuyện mới", chọn 1 đồng nghiệp 3. Bấm "Tạo" | G38: Đồng nghiệp: Trần Thị Bình | H38: Mở khung chat với đồng nghiệp đã chọn | I38: Employee | J38: Cao | K38: Đạt | L38: 46321 | M38: Nhóm kiểm thử
A39: TC-35 | B39: Nhắn tin | C39: ConversationsPage | D39: Không tạo trùng hội thoại 1:1 | E39: Đã có hội thoại 1:1 với đồng nghiệp | F39: 1. Tạo lại hội thoại 1:1 với cùng đồng nghiệp | G39: — | H39: Mở lại hội thoại cũ, danh sách không có hội thoại trùng | I39: Employee | J39: Trung bình | K39: Đạt | L39: 46321 | M39: Nhóm kiểm thử
A40: TC-36 | B40: Nhắn tin | C40: ConversationsPage | D40: Tạo nhóm thiếu tên | E40: Đang tạo cuộc trò chuyện mới | F40: 1. Chọn từ 2 đồng nghiệp trở lên 2. Để trống tên nhóm 3. Bấm "Tạo" | G40: 2 đồng nghiệp | H40: Hiện "Nhóm từ 2 người trở lên bắt buộc phải có tên" | I40: Employee | J40: Trung bình | K40: Đạt | L40: 46321 | M40: Nhóm kiểm thử
A41: TC-37 | B41: Nhắn tin | C41: ChatPage | D41: Gửi và nhận tin nhắn tức thời | E41: Hai tài khoản đăng nhập trên hai thiết bị | F41: 1. Tài khoản A gửi tin trong hội thoại 2. Quan sát trên thiết bị của tài khoản B | G41: Tin nhắn ngắn | H41: B nhận tin ngay (WebSocket); danh sách hội thoại của B tăng số tin chưa đọc | I41: Employee | J41: Cao | K41: Đạt | L41: 46321 | M41: Nhóm kiểm thử
...

Sheet Danh sách
A1: Danh sách giá trị
A4: Trạng thái | B4: Mức ưu tiên
A5: Chưa chạy | B5: Cao
A6: Đạt | B6: Trung bình
A7: Không đạt | B7: Thấp
A8: Bị chặn
