Workbook

Sheet Thông tin
A1: Bảng thông số kỹ thuật sản phẩm trong kho
A3: Dự án | B3: Website bán hàng SME
A4: Nền tảng | B4: ECAP — nền tảng cộng tác và phân tích dữ liệu cho doanh nghiệp vừa và nhỏ
A5: Đơn vị | B5: Công ty Demo SME (kinh doanh máy tính, linh kiện và phụ kiện)
A6: Người đọc | B6: Nhóm nội dung website, bộ phận kinh doanh
A7: Phiên bản | B7: 1.0
A8: Ngày phát hành | B8: 46321
A9: Phân loại | B9: Tài liệu nội bộ — Công ty Demo SME — dùng cho mục đích minh hoạ đồ án
A10: Số liệu | B10: Đơn giá là số liệu minh hoạ (giá tham khảo). Thông số kỹ thuật là dữ liệu đã kiểm chứng, có ghi nguồn.
A12: Chú giải
A13: Giá trị mẫu | B13: Ô nhập liệu (nền vàng, chữ xanh): người dùng được sửa hoặc nhập mới; mọi công thức tự tính lại.
A14: Công thức | B14: Ô công thức (nền trắng, chữ đen): tính tự động, không nhập đè.
A15: Tiêu đề | B15: Dòng tiêu đề bảng: đã cố định (freeze) và bật bộ lọc.
A17: Cấu trúc workbook
A18: Tổng hợp | B18: Đếm SKU theo danh mục, mức xác minh và khoảng giá bằng công thức COUNTA/COUNTIF/MIN/MAX/AVERAGE.
A19: Laptop | B19: 3 SKU laptop, mỗi thông số một cột.
A20: PC | B20: 2 SKU PC để bàn, thông số chính gộp trong một ô.
A21: Linh kiện | B21: 9 SKU linh kiện PC (2 CPU, RAM, SSD, card đồ hoạ, bo mạch chủ, nguồn, vỏ case, tản nhiệt).
A22: Màn hình | B22: 2 SKU màn hình, mỗi thông số một cột.
A23: Phụ kiện | B23: 3 SKU phụ kiện (bàn phím, chuột, tai nghe).
A24: Chi tiết thông số | B24: Mỗi dòng một thông số của một SKU, kèm đơn vị, nguồn chính và nguồn đối chiếu.
A26: Giả định và nguồn dữ liệu
A27: 1. | B27: Danh sách sản phẩm, SKU, danh mục và đơn giá lấy từ dữ liệu mẫu kho của ECAP (scripts/seed-inventory.js, 19 SKU).
A28: 2. | B28: Đơn giá là giá thị trường Việt Nam tham khảo (VND), không phải giá niêm yết chính thức — số liệu minh hoạ. Ô đơn giá là ô nhập liệu.
A29: 3. | B29: Thông số kỹ thuật lấy từ bộ dữ liệu đã kiểm chứng ngày 26/10/2026; mỗi SKU có cột Nguồn (URL) và sheet Chi tiết thông số ghi nguồn cho từng giá trị.
A30: 4. | B30: Mức xác minh: "Đã xác minh" = model rõ ràng, thông số khớp nguồn; "Đã đối chiếu — model suy luận" = model suy ra từ ảnh/mô tả, thông số đã đối chiếu; "Cấu hình tham khảo" = chưa xác nhận đúng model (màn hình cong BenQ, vỏ case ATX).
A31: 5. | B31: Đính chính RAM: Kingston HyperX KHX6400S2ULK2/4G là kit 2x2 GB (tổng 4 GB), không phải 2x4 GB như tên trong kho — xem ghi chú ở sheet Linh kiện.
A32: 6. | B32: Đơn vị đi kèm giá trị: nếu giá trị đã chứa đơn vị thì giữ nguyên, nếu không thì ghi thêm "(đơn vị: ...)".

Sheet Tổng hợp
A1: Tổng hợp SKU theo danh mục
A2: Mọi ô số trong bảng là công thức tham chiếu các sheet danh mục.
A4: Danh mục | B4: Sheet | C4: Số SKU | D4: Đã xác minh | E4: Model suy luận (đã đối chiếu) | F4: Cấu hình tham khảo | G4: Đơn giá thấp nhất (VND) | H4: Đơn giá cao nhất (VND) | I4: Đơn giá trung bình (VND) | J4: Số dòng thông số
A5: Laptop | B5: Laptop | C5: =COUNTA(Laptop!$B$5:$B$60) -> 3 | D5: =COUNTIF(Laptop!$S$5:$S$60,"Đã xác minh") -> 2 | E5: =COUNTIF(Laptop!$S$5:$S$60,"Đã đối chiếu*") -> 1 | F5: =COUNTIF(Laptop!$S$5:$S$60,"Cấu hình tham khảo") -> 0 | G5: =IFERROR(MIN(Laptop!$R$5:$R$60),0) -> 14900000 | H5: =IFERROR(MAX(Laptop!$R$5:$R$60),0) -> 26900000 | I5: =IFERROR(AVERAGE(Laptop!$R$5:$R$60),0) -> 20233333 | J5: =COUNTIF('Chi tiết thông số'!$C$5:$C$375,A5) -> 32
A6: PC để bàn | B6: PC | C6: =COUNTA(PC!$B$5:$B$60) -> 2 | D6: =COUNTIF(PC!$H$5:$H$60,"Đã xác minh") -> 0 | E6: =COUNTIF(PC!$H$5:$H$60,"Đã đối chiếu*") -> 2 | F6: =COUNTIF(PC!$H$5:$H$60,"Cấu hình tham khảo") -> 0 | G6: =IFERROR(MIN(PC!$G$5:$G$60),0) -> 8900000 | H6: =IFERROR(MAX(PC!$G$5:$G$60),0) -> 24500000 | I6: =IFERROR(AVERAGE(PC!$G$5:$G$60),0) -> 16700000 | J6: =COUNTIF('Chi tiết thông số'!$C$5:$C$375,A6) -> 21
A7: Linh kiện PC | B7: Linh kiện | C7: =COUNTA('Linh kiện'!$B$5:$B$60) -> 9 | D7: =COUNTIF('Linh kiện'!$I$5:$I$60,"Đã xác minh") -> 8 | E7: =COUNTIF('Linh kiện'!$I$5:$I$60,"Đã đối chiếu*") -> 0 | F7: =COUNTIF('Linh kiện'!$I$5:$I$60,"Cấu hình tham khảo") -> 1 | G7: =IFERROR(MIN('Linh kiện'!$H$5:$H$60),0) -> 450000 | H7: =IFERROR(MAX('Linh kiện'!$H$5:$H$60),0) -> 14900000 | I7: =IFERROR(AVERAGE('Linh kiện'!$H$5:$H$60),0) -> 5783333.3 | J7: =COUNTIF('Chi tiết thông số'!$C$5:$C$375,A7) -> 80
A8: Màn hình | B8: Màn hình | C8: =COUNTA('Màn hình'!$B$5:$B$60) -> 2 | D8: =COUNTIF('Màn hình'!$T$5:$T$60,"Đã xác minh") -> 1 | E8: =COUNTIF('Màn hình'!$T$5:$T$60,"Đã đối chiếu*") -> 0 | F8: =COUNTIF('Màn hình'!$T$5:$T$60,"Cấu hình tham khảo") -> 1 | G8: =IFERROR(MIN('Màn hình'!$S$5:$S$60),0) -> 1990000 | H8: =IFERROR(MAX('Màn hình'!$S$5:$S$60),0) -> 7900000 | I8: =IFERROR(AVERAGE('Màn hình'!$S$5:$S$60),0) -> 4945000 | J8: =COUNTIF('Chi tiết thông số'!$C$5:$C$375,A8) -> 21
A9: Phụ kiện | B9: Phụ kiện | C9: =COUNTA('Phụ kiện'!$B$5:$B$60) -> 3 | D9: =COUNTIF('Phụ kiện'!$H$5:$H$60,"Đã xác minh") -> 0 | E9: =COUNTIF('Phụ kiện'!$H$5:$H$60,"Đã đối chiếu*") -> 3 | F9: =COUNTIF('Phụ kiện'!$H$5:$H$60,"Cấu hình tham khảo") -> 0 | G9: =IFERROR(MIN('Phụ kiện'!$G$5:$G$60),0) -> 450000 | H9: =IFERROR(MAX('Phụ kiện'!$G$5:$G$60),0) -> 1890000 | I9: =IFERROR(AVERAGE('Phụ kiện'!$G$5:$G$60),0) -> 1263333.3 | J9: =COUNTIF('Chi tiết thông số'!$C$5:$C$375,A9) -> 17
A10: Tổng cộng | C10: =SUM(C5:C9) -> 19 | D10: =SUM(D5:D9) -> 11 | E10: =SUM(E5:E9) -> 6 | F10: =SUM(F5:F9) -> 2 | G10: =MIN(G5:G9) -> 450000 | H10: =MAX(H5:H9) -> 26900000 | I10: =IFERROR((SUM(Laptop!$R$5:$R$60)+SUM(PC!$G$5:$G$60)+SUM('Linh kiện'!$H$5:$H$60)+SUM('Màn hình'!$S$5:$S$60)+SUM('Phụ kiện'!$G$5:$G$60))/C10,0) -> 8412105.3 | J10: =SUM(J5:J9) -> 171
A12: Số SKU trong danh sách kho | B12: seed-inventory.js | C12: 19
A13: Kiểm tra đối chiếu | B13: Tổng SKU so với danh sách kho | C13: =IF(C10=C12,"Khớp","Lệch") -> Khớp
A14: Tỷ lệ SKU đã xác minh đầy đủ | B14: Đã xác minh / Tổng SKU | C14: =IFERROR(D10/C10,0) -> 0.57894737
A16: Ghi chú: ô vàng C12 là số SKU kỳ vọng theo dữ liệu mẫu kho (19 SKU) — số nhập tay để đối chiếu.

Sheet Laptop
A1: Thông số kỹ thuật — Laptop
A2: Đơn giá tham khảo là số liệu minh hoạ; thông số đã kiểm chứng ngày 26/10/2026, nguồn ở cột cuối.
A4: STT | B4: SKU | C4: Tên sản phẩm (trong kho) | D4: Model xác định | E4: Mô tả | F4: CPU | G4: Chipset | H4: RAM | I4: Lưu trữ | J4: Màn hình | K4: Đồ hoạ (GPU) | L4: Trọng lượng | M4: Pin | N4: Cổng kết nối | O4: Ổ quang | P4: Hệ điều hành khi ra mắt | Q4: Năm ra mắt | R4: Đơn giá tham khảo (VND) | S4: Mức xác minh | T4: Ngày kiểm chứng | U4: Ghi chú | V4: Nguồn
A5: 1 | B5: LAP-DELL-XPSM1330 | C5: Laptop Dell XPS M1330 | D5: Dell XPS M1330 (13.3", 2007-2008) | E5: Laptop 13,3 inch dòng XPS của Dell ra mắt năm 2007, dùng Intel Core 2 Duo và card rời GeForce 8400M GS. Máy mỏng nhẹ so với các laptop cùng thời, có ổ DVD dạng khe. | F5: Intel Core 2 Duo, tuỳ cấu hình (vd. T7300 2.0 GHz; bản Penryn 2008: T9300 2.5 GHz) | G5: Intel PM965 (Crestline) + ICH8M | H5: 1-2 GB DDR2-667 (tuỳ cấu hình), tối đa 4 GB | I5: HDD SATA 5400 rpm, 120-160 GB tuỳ cấu hình | J5: 13,3 inch, 1280x800 (16:10), có tuỳ chọn đèn nền LED | K5: NVIDIA GeForce 8400M GS 128 MB | L5: khoảng 1,8 (pin 6 cell); khoảng 2,0 (4,5 lb) với pin 9 cell (đơn vị: kg) | M5: Li-ion 6 cell 56 Wh; tuỳ chọn pin 9 cell | N5: 2x USB 2.0, HDMI, VGA, FireWire, S-Video, LAN, modem, ExpressCard, mic, 2x tai nghe, khoá Kensington | O5: DVD±RW dạng khe (slot-loading) | P5: Windows Vista Home Premium | Q5: 2007 (ra mắt 26/06/2007) | R5: 18900000 | S5: Đã xác minh | T5: 46321 | U5: Mô tả trong kho ghi "vỏ nhôm": chưa xác minh được chất liệu vỏ, nên kiểm tra lại Chưa tìm thấy nguồn: Danh sách đầy đủ CPU tuỳ chọn từ Dell (trang gốc không còn); Hãng không công bố thời lượng pin chính thức; Laptop Mag đo được khoảng 5,5 giờ | V5: https://www.notebookcheck.net/Dell-XPS-M1330.5463.0.html https://www.laptopmag.com/reviews/laptops/dell-xps-m1330-penryn
A6: 2 | B6: LAP-LENOVO-T460 | C6: Laptop Lenovo ThinkPad T460 | D6: Lenovo ThinkPad T460 (2016, Intel Core thế hệ 6) | E6: Laptop doanh nhân 14 inch dùng Intel Core thế hệ 6 (Skylake), ra mắt năm 2016. Máy hỗ trợ hệ thống pin kép Power Bridge và đạt chuẩn độ bền MIL-STD-810G. | F6: Intel Core i3-6100U / i5-6200U / i5-6300U / i7-6500U / i7-6600U (2 nhân 4 luồng) | G6: — | H6: Tối đa 32 GB DDR3L-1600, 2 khe SO-DIMM, dual-channel | I6: SSD SATA, SSD PCIe NVMe (PCIe 3.0 x2), HDD 2,5" hoặc SSHD (tuỳ cấu hình) | J6: 14 inch HD 1366x768 TN hoặc FHD 1920x1080 IPS; tuỳ chọn cảm ứng | K6: Intel HD Graphics 520; tuỳ chọn NVIDIA GeForce 940MX 2 GB | L6: từ 1,73 (3+3 cell, không cảm ứng) (đơn vị: kg) | M6: Pin trong 3 cell 23 Wh (tuỳ cấu hình, có bản không có pin trong) + pin ngoài 3 cell 23 Wh hoặc 6 cell 48/72 Wh (Power Bridge) | N6: 3x USB 3.0, HDMI, Mini DisplayPort, RJ-45, cổng dock, đầu đọc thẻ 4-in-1, jack âm thanh combo; tuỳ chọn smart card | O6: — | P6: Windows 10 Pro 64-bit hoặc Windows 7 Pro (hạ cấp từ Windows 10 Pro) | Q6: 2016 (công bố tại CES tháng 1/2016) | R6: 14900000 | S6: Đã xác minh | T6: 46321 | U6: Chưa tìm thấy nguồn: Cấu hình cụ thể của máy trong kho (dữ liệu kho không ghi CPU/RAM/ổ cứng) | V6: https://psref.lenovo.com/syspool/Sys/PDF/ThinkPad/ThinkPad_T460/ThinkPad_T460_Spec.PDF https://pcper.com/2016/01/ces-2016-lenovo-announces-thinkpad-t460-series-notebooks/
A7: 3 | B7: LAP-HP-ENVY14 | C7: Laptop HP Envy 14 | D7: HP ENVY Laptop 14-eb0021TX (Core i7-1165G7, GTX 1650 Ti Max-Q) | E7: Laptop 14 inch màn hình 16:10 dùng Intel Core i7 thế hệ 11 và card rời GeForce GTX 1650 Ti Max-Q, phù hợp làm đồ hoạ và sáng tạo nội dung. Vỏ kim loại, nặng khoảng 1,5 kg. | F7: Intel Core i7-1165G7, 4 nhân 8 luồng, 2,8-4,7 GHz | G7: — | H7: 16 GB DDR4-3200 | I7: SSD PCIe NVMe 1 TB | J7: 14 inch IPS 1920x1200 (16:10), 60 Hz | K7: NVIDIA GeForce GTX 1650 Ti Max-Q 4 GB GDDR6 + Intel Iris Xe | L7: 1,49 kg | M7: 63,3 Wh, 4 cell Li-Po | N7: 2x USB-A 5 Gbps, 1x Thunderbolt (USB-C), HDMI, jack 3,5 mm, khe microSD | O7: — | P7: Windows 10 Home 64-bit | Q7: 2021 (công bố tại CES tháng 1/2021, giá từ 999 USD) | R7: 26900000 | S7: Đã đối chiếu — model suy luận | T7: 46321 | U7: Giả định model: Dữ liệu kho chỉ ghi "Envy 14, Core i7 + GeForce GTX, viền mỏng". Ảnh có tem Intel Core i7 thế hệ 11 và NVIDIA GeForce GTX, khớp dòng Envy 14-eb0 (2021). Chọn mã 14-eb0021TX vì đuôi TX là bản bán ở châu Á. Chưa tìm thấy nguồn: RAM hàn chết hay nâng cấp được, dung lượng tối đa; Datasheet chính thức của HP cho mã 14-eb0021TX | V7: https://www.notebookcheck.net/HP-Envy-14-eb0021tx.602559.0.html https://windowscentral.com/hp-unveils-new-envy-14-intel-11th-gen-chips-and-dedicated-nvidia-gtx-1650-graphics

Sheet PC
A1: Thông số kỹ thuật — PC để bàn
A2: Đơn giá tham khảo là số liệu minh hoạ; thông số đã kiểm chứng ngày 26/10/2026, nguồn ở cột cuối.
A4: STT | B4: SKU | C4: Tên sản phẩm (trong kho) | D4: Model xác định | E4: Mô tả | F4: Thông số chính | G4: Đơn giá tham khảo (VND) | H4: Mức xác minh | I4: Ngày kiểm chứng | J4: Ghi chú | K4: Nguồn
A5: 1 | B5: PC-GAMING-FRACTAL-TUF | C5: PC Gaming Fractal Design TUF Edition | D5: PC gaming lắp ráp: vỏ Fractal Design Focus G (Petrol Blue) với linh kiện ASUS TUF Gaming | E5: Máy tính gaming lắp ráp trong vỏ Fractal Design Focus G màu xanh Petrol Blue, có cửa sổ hông bằng mica và quạt LED trắng. Máy dùng CPU AMD Ryzen, mainboard ASUS TUF Gaming và card đồ hoạ GeForce GTX. | F5: Kiểu dáng: Vỏ ATX Mid Tower (hỗ trợ ATX / Micro-ATX / Mini-ITX), 7 khe mở rộng Tuỳ chọn CPU: AMD Ryzen socket AM4 (nhìn thấy tản AMD Wraith Prism; chưa xác định model CPU) Đồ hoạ (GPU): ASUS Cerberus GeForce GTX (model cụ thể chưa xác định) Lưu trữ: Vỏ có 2x 5.25", 2x 3,5"/2,5", 1x 2,5" chuyên dụng (ảnh: 1 HDD 3,5" + 1 SSD 2,5") Cổng mặt trước: 1x USB 2.0, 1x USB-A 5 Gbps, jack tai nghe, jack mic Quạt: 2x Fractal Silent LL 120 mm LED trắng (phía trước); tối đa 6 vị trí quạt VGA dài tối đa: 380 mm Tản CPU cao tối đa: 165 mm Kích thước vỏ: 464 x 205 x 444 (D x R x C), 4,5 kg (đơn vị: mm) Nắp hông: Tấm hông thép có cửa sổ lớn bằng mica (acrylic), không phải kính cường lực | G5: 24500000 | H5: Đã đối chiếu — model suy luận | I5: 46321 | J5: Giả định model: Fractal Design không có sản phẩm nào tên "TUF Edition". Ảnh là máy lắp ráp: vỏ Focus G màu Petrol Blue (khoang 5.25" có logo fractal, quạt trước LED trắng, gắn tem ASUS TUF Gaming), mainboard ASUS TUF Gaming, tản AMD Wraith Prism (nên CPU là Ryzen AM4), VGA ASUS Cerberus GeForce GTX, RAM G.Skill. Chỉ xác minh được thông số của vỏ. Chưa tìm thấy nguồn: Model CPU, mainboard, VGA, dung lượng RAM/ổ cứng, nguồn; RAM tối đa (phụ thuộc mainboard); Cổng I/O phía sau (phụ thuộc mainboard) | K5: https://www.fractal-design.com/products/cases/focus/focus-g/white/ Ảnh sản phẩm trong kho (pc-gaming-fractal-tuf.webp): nhãn, tem nhìn thấy trên ảnh https://www.memoryexpress.com/Products/MX70610
A6: 2 | B6: PC-OFFICE-OPTIPLEX9020 | C6: PC Văn phòng Dell OptiPlex 9020 | D6: Dell OptiPlex 9020 Small Form Factor (SFF) | E6: Máy bộ văn phòng Dell OptiPlex 9020 vỏ nhỏ gọn (SFF), dùng chipset Intel Q87 và CPU Intel Core thế hệ 4. Phù hợp cho tác vụ hành chính, kế toán và văn phòng. | F6: Tuỳ chọn CPU: Intel Core i7/i5 thế hệ 4 (4 nhân, 84 W), Core i3 / Pentium (2 nhân); socket LGA1150 Chipset: Intel Q87 Express RAM tối đa: 32 GB DDR3-1600 non-ECC, 4 khe DIMM, dual-channel Lưu trữ: 1 khoang 3,5" trong + 1 khoang 5.25" slim ngoài; HDD tối đa 2 TB, hỗ trợ SSD/SSHD, RAID 0/1 Khe mở rộng: 1x PCIe x16 low-profile + 1x PCIe x16 (chạy x4) low-profile Cổng kết nối: 4x USB 3.0 (2 trước, 2 sau), 6x USB 2.0 (2 trước, 4 sau), RJ-45, Serial, VGA, 2x DisplayPort, 2x PS/2, line-in, line-out Đồ hoạ: Intel HD Graphics 4600; hỗ trợ card rời low-profile Mạng: Intel I217LM Gigabit Ethernet Nguồn (PSU): 255 W (tuỳ chọn bản hiệu suất 90%, 80 PLUS Gold) Kiểu dáng: SFF, 29,0 x 9,3 x 31,2 cm (C x R x S), từ 6,0 kg Hệ điều hành khi ra mắt: Windows 7 Professional SP1 / Windows 8.1 (Pro) / Ubuntu | G6: 8900000 | H6: Đã đối chiếu — model suy luận | I6: 46321 | J6: Giả định model: Dữ liệu kho không ghi kiểu vỏ (OptiPlex 9020 có MT, SFF, USFF, Micro). Ảnh là vỏ nằm ngang có ổ DVD slim và 4 cổng USB phía trước, khớp bản SFF. Chưa tìm thấy nguồn: Ngày ra mắt chính thức (khoảng 2013, chưa có nguồn) | K6: https://i.dell.com/sites/csdocuments/Corporate_secure_Documents/en/OptiPlex-9020-micro-spec.PDF

Sheet Linh kiện
A1: Thông số kỹ thuật — Linh kiện PC
A2: Đơn giá tham khảo là số liệu minh hoạ; thông số đã kiểm chứng ngày 26/10/2026, nguồn ở cột cuối.
A3: Lưu ý: RAM Kingston HyperX (RAM-KINGSTON-HYPERX-SODIMM) thực tế là kit 2x2 GB (tổng 4 GB) theo datasheet KHX6400S2ULK2/4G, không phải 2x4 GB như tên trong kho.
A4: STT | B4: SKU | C4: Tên sản phẩm (trong kho) | D4: Loại linh kiện | E4: Model xác định | F4: Mô tả | G4: Thông số chính | H4: Đơn giá tham khảo (VND) | I4: Mức xác minh | J4: Ngày kiểm chứng | K4: Ghi chú | L4: Nguồn
A5: 1 | B5: CPU-INTEL-I9-9900K | C5: CPU Intel Core i9-9900K | D5: CPU | E5: Intel Core i9-9900K (Coffee Lake Refresh) | F5: CPU desktop Intel Core thế hệ 9 với 8 nhân 16 luồng, xung tối đa 5,0 GHz, mở khoá hệ số nhân để ép xung. Dùng socket LGA1151 và có sẵn đồ hoạ tích hợp UHD 630. | G5: Nhân/Luồng: 8 / 16 Xung cơ bản: 3,60 GHz Xung tăng tốc: 5,00 (Max Turbo) (đơn vị: GHz) Bộ nhớ đệm: 16 MB Intel Smart Cache TDP: 95 W Socket: FCLGA1151 Bộ nhớ hỗ trợ: DDR4-2666, tối đa 128 GB GPU tích hợp: Intel UHD Graphics 630 Ngày ra mắt: Q4/2018 | H5: 7200000 | I5: Đã xác minh | J5: 46321 | L5: https://www.intel.com/content/www/us/en/products/sku/186605/intel-core-i99900k-processor-16m-cache-up-to-5-00-ghz/specifications.html
A6: 2 | B6: CPU-AMD-R9-3900X | C6: CPU AMD Ryzen 9 3900X | D6: CPU | E6: AMD Ryzen 9 3900X (Zen 2 "Matisse") | F6: CPU desktop AMD Ryzen 9 thế hệ 3000 với 12 nhân 24 luồng, tiến trình 7 nm, xung tối đa 4,6 GHz. Dùng socket AM4, hỗ trợ PCIe 4.0, phù hợp đa nhiệm và render. | G6: Nhân/Luồng: 12 / 24 Xung cơ bản: 3,8 GHz Xung tăng tốc: tối đa 4,6 (đơn vị: GHz) Bộ nhớ đệm: L2 6 MB, L3 64 MB TDP: 105 W Socket: AM4 Bộ nhớ hỗ trợ: DDR4, tối đa 3200 MT/s, dual-channel Tiến trình: 7 nm TSMC (2 chiplet CCD) + I/O die 12 nm, kiến trúc Zen 2 Ngày ra mắt: 07/07/2019 Tản kèm hộp: AMD Wraith Prism (LED RGB), kèm trong hộp | H6: 6500000 | I6: Đã xác minh | J6: 46321 | L6: https://www.amd.com/en/products/processors/desktops/ryzen/3000-series/amd-ryzen-9-3900x.html https://techpowerup.com/cpu-specs/ryzen-9-3900x.c2128 https://en.wikipedia.org/wiki/Zen_2
A7: 3 | B7: RAM-KINGSTON-HYPERX-SODIMM | C7: RAM Laptop Kingston HyperX SO-DIMM (Kit 2x4GB) | D7: RAM | E7: Kingston HyperX KHX6400S2ULK2/4G (kit 2x2 GB DDR2-800 SO-DIMM) | F7: Bộ RAM laptop Kingston HyperX DDR2-800 (PC2-6400) gồm 2 thanh 2 GB, tổng 4 GB, độ trễ thấp CL4. Chuẩn SO-DIMM 200 chân, điện áp 1,8 V. | G7: Loại: DDR2 SO-DIMM 200 chân, non-ECC unbuffered, 2Rx8 Dung lượng kit: 4 GB (2 x 2 GB) Tốc độ: DDR2-800 (PC2-6400); profile phụ DDR2-667 (đơn vị: MT/s) Độ trễ (CL): CL4-4-4-12 @ 800 MHz (CL3-4-4-10 @ 667 MHz) Điện áp: 1,8 (±0,1) (đơn vị: V) Bảo hành: Trọn đời (Lifetime) Ngày ra mắt: Công bố 03/09/2008 | H7: 650000 | I7: Đã xác minh | J7: 46321 | K7: ĐÍNH CHÍNH: theo datasheet Kingston KHX6400S2ULK2/4G đây là kit 2x2 GB (tổng 4 GB), không phải 2x4 GB như tên sản phẩm trong kho. | L7: https://www.kingston.com/dataSheets/KHX6400S2ULK2_4G.pdf Ảnh sản phẩm trong kho (ram-kingston-hyperx-sodimm.webp): nhãn, tem nhìn thấy trên ảnh https://www.hothardware.com/News/Kingston-Launches-Low-Latency-Notebook-Memory
A8: 4 | B8: SSD-SAMSUNG-870QVO-8TB | C8: SSD Samsung 870 QVO 8TB | D8: SSD | E8: Samsung 870 QVO 8TB (MZ-77Q8T0) | F8: SSD SATA 2,5 inch dung lượng 8 TB dùng chip nhớ QLC V-NAND của Samsung, tốc độ đọc/ghi tuần tự tới 560/530 MB/s. Phù hợp lưu trữ dung lượng lớn thay cho HDD. | G8: Dung lượng: 8 TB Giao tiếp: SATA 6 Gb/s (tương thích 3 / 1,5 Gb/s) Kiểu dáng: 2,5 inch, 100 x 69,85 x 6,8 mm, khoảng 57 g NAND: Samsung V-NAND 4-bit MLC (QLC) Bộ điều khiển: Samsung MKX Bộ nhớ đệm: 8 GB LPDDR4 (Samsung Low Power DDR4 SDRAM) Đọc tuần tự: 560 MB/s Ghi tuần tự: 530 (Intelligent TurboWrite) (đơn vị: MB/s) Ngẫu nhiên QD32: 98.000 / 88.000 IOPS (đọc/ghi 4KB) Độ bền ghi (TBW): 2.880 TB Bảo hành: 3 năm hoặc hết TBW (tuỳ điều kiện nào đến trước) Ngày ra mắt: Công bố 30/06/2020 (bản 8 TB giao từ tháng 8/2020) | H8: 14900000 | I8: Đã xác minh | J8: 46321 | L8: https://www.samsung.com/ca/memory-storage/870-qvo-sata-3-2-5-ssd/MZ-77Q8T0BAM https://www.samsung.com/sg/business/memory-storage/sata-ssd/870-qvo-sata-3-2-5-ssd-mz-77q8t0bw/ https://www.sammobile.com/new/samsung-launches-870-qvo-ssd-series-8tb-storage/
A9: 5 | B9: GPU-MSI-RTX3070-VENTUS3X | C9: Card đồ họa MSI GeForce RTX 3070 Ventus 3X OC | D9: Card đồ hoạ | E9: MSI GeForce RTX 3070 VENTUS 3X OC (bản gốc 2020, không LHR) | F9: Card đồ hoạ MSI RTX 3070 Ventus 3X OC dùng 3 quạt, 8 GB GDDR6, xung boost 1755 MHz. Phù hợp chơi game 1440p và hỗ trợ ray tracing, DLSS. | G9: Chip đồ hoạ: NVIDIA GA104-300 (Ampere), 5888 CUDA cores VRAM: 8 GB GDDR6, 256-bit, 14 Gbps Xung tăng tốc: 1755 MHz Giao tiếp: PCI Express 4.0 x16 Công suất card: 220 W PSU khuyến nghị: 650 W Đầu cấp nguồn: 2x 8-pin Cổng xuất hình: 3x DisplayPort 1.4a, 1x HDMI 2.1 Kích thước: 305 x 121 x 52 mm (dài x cao x dày); tản choán sang khe thứ 3; nặng 991,6 g | H9: 13900000 | I9: Đã xác minh | J9: 46321 | L9: https://www.notebookcheck.net/NVIDIA-GeForce-RTX-3070-confirmed-to-be-using-the-GA104-300-GPU.496247.0.html https://www.msi.com/Graphics-Card/GeForce-RTX-3070-VENTUS-3X-OC/Specification https://www.servethehome.com/msi-geforce-rtx-3070-ventus-3x-oc-edition-review-nvidia/ https://storage-asset.msi.com/datasheet/vga/kr/GeForce-RTX-3070-VENTUS-3X-OC.pdf
A10: 6 | B10: MB-ASUS-ROG-STRIXZ390F | C10: Bo mạch chủ ASUS ROG Strix Z390-F Gaming | D10: Bo mạch chủ | E10: ASUS ROG STRIX Z390-F GAMING | F10: Bo mạch chủ ATX chipset Intel Z390, socket LGA1151, hỗ trợ CPU Intel Core thế hệ 8/9 và ép xung. Có 2 khe M.2, mạng Intel Gigabit và USB 3.1 Gen 2. | G10: Socket: LGA1151 (Intel Core thế hệ 8/9) Chipset: Intel Z390 Kiểu dáng: ATX, 30,5 x 24,4 cm Khe RAM/tối đa: 4 khe DIMM DDR4, tối đa 128 GB, 2133 đến 4266 MHz (OC) Khe M.2: 2 khe M.2: #1 SATA/PCIe 3.0 x4 (2242-2280), #2 PCIe 3.0 x4 (2242-22110) SATA: 6x SATA 6 Gb/s Mạng: Intel I219V Gigabit LAN; không có Wi-Fi USB phía sau: 4x USB 3.1 Gen 2 (3 Type-A + 1 Type-C), 2x USB 3.1 Gen 1, 2x USB 2.0 | H10: 4500000 | I10: Đã xác minh | J10: 46321 | L10: https://rog.asus.com/motherboards/rog-strix/rog-strix-z390-f-gaming-model/spec/
A11: 7 | B11: PSU-OCZ-600W | C11: Nguồn máy tính OCZ 600W | D11: Nguồn | E11: OCZ ModXStream Pro 600W (OCZ600MXSP) | F11: Nguồn máy tính OCZ ModXStream Pro công suất 600 W, đạt chuẩn 80 PLUS, thiết kế bán module. Có PFC chủ động và quạt 135 mm. | G11: Công suất: 600 W Hiệu suất: 80 PLUS (mức tiêu chuẩn/White) Kiểu dây: Bán module: dây 24-pin, ATX12V, EPS12V cố định; dây PCIe/SATA/Molex/FDD tháo rời Kiểu dáng: ATX12V / EPS12V Quạt: 135 mm PFC: Active PFC Đầu cắm: PCIe: 1x 6-pin + 1x 6+2-pin; 6x SATA; 4x Molex; 2x FDD; 1x EPS12V 8-pin; 1x ATX12V 4-pin (EPS/ATX12V cố định) Năm phát hành: khoảng 2009-2010 (review Hardware Secrets 25/02/2010) | H11: 1850000 | I11: Đã xác minh | J11: 46321 | K11: Chưa tìm thấy nguồn: Datasheet chính thức OCZ (sản phẩm đã ngừng, OCZ không còn kinh doanh nguồn); Thời hạn bảo hành (các nguồn bán lẻ ghi 3 năm, chưa xác minh); Dòng các rail +12V | L11: Ảnh sản phẩm trong kho (psu-ocz-600w.webp): nhãn, tem nhìn thấy trên ảnh https://www.buildcores.com/products/PSU/r7djvf1l6/OCZ-ModXStream-Pro-600W-Semi-Modular-80%2B https://hardwaresecrets.com/ocz-modxstream-pro-600-w-power-supply-review/
A12: 8 | B12: CASE-ATX-GAMING | C12: Case Gaming ATX | D12: Vỏ case | E12: Fractal Design Define R5 (Black) | F12: Vỏ máy ATX mid tower cách âm Fractal Design Define R5, có 2 khoang 5.25" và tối đa 8 khay ổ 3,5"/2,5". Đi kèm 2 quạt 140 mm, hỗ trợ card đồ hoạ dài tới 440 mm khi tháo lồng ổ phía trên. | G12: Mainboard hỗ trợ: ATX / Micro-ATX / Mini-ITX, 7 khe mở rộng Quạt kèm theo: 2x Fractal Dynamic GP-14 140 mm (1 trước, 1 sau) Vị trí quạt: Trước 2, trên 3, hông 1, đáy 2, sau 1 (120/140 mm) Radiator: Trên tối đa 420 mm; trước tối đa 360 mm; đáy 240 mm; sau 140 mm VGA dài tối đa: 440 mm Tản CPU cao tối đa: 180 mm PSU dài tối đa: 190 (ATX) (đơn vị: mm) Khoang ổ đĩa: 2x 5.25", 8x 3,5"/2,5", 2x 2,5" chuyên dụng Cổng mặt trước: 2x USB 2.0, 2x USB-A 5 Gbps, jack tai nghe, jack mic Kích thước/Trọng lượng: 531 x 232 x 462 mm, 10,7 kg | H12: 2100000 | I12: Cấu hình tham khảo | J12: 46321 | K12: Giả định model: Dữ liệu kho và tên ảnh không ghi hãng. Ảnh chụp nội thất vỏ ATX mid tower màu đen: cụm 2 khoang 5.25" ở góc trên phía trước, lồng HDD 5 khay bên dưới, không có tấm che PSU, đáy và mặt sau đục lỗ. Bố cục này khớp Define R5 khi đã tháo lồng HDD phía trên. Độ tin cậy thấp, nên thay bằng model thực tế nếu biết. Cấu hình tham khảo — chưa xác nhận đúng model của hàng trong kho. Chưa tìm thấy nguồn: Model thật của vỏ trong ảnh (chưa xác định được) | L12: https://www.fractal-design.com/products/cases/define/define-r5/black/
A13: 9 | B13: COOLER-ARCTIC-FREEZER13 | C13: Tản nhiệt khí Arctic Freezer 13 | D13: Tản nhiệt | E13: ARCTIC Freezer 13 | F13: Tản nhiệt khí dạng tháp ARCTIC Freezer 13 dùng quạt 92 mm PWM và ống dẫn nhiệt đồng 6 mm, hỗ trợ nhiều socket Intel và AMD. Có sẵn keo tản nhiệt MX-4, vận hành êm (0,5 sone). | G13: Socket hỗ trợ: Intel 1150, 1151, 1155, 1156, 1366, 775; AMD AM4, AM3(+), AM2(+), FM2(+), FM1 Ống dẫn nhiệt: 3 ống chữ U Ø6 mm, đi xuyên hai bên khối tản (6 đầu ống), theo bảng thông số hiện hành (r6, 2018); bản đầu năm 2010 dùng 4 ống chữ U Ø6 mm Quạt: 92 mm PWM, 600-2000 RPM, bạc đạn Fluid Dynamic, 0,5 sone TDP khuyến nghị: Khuyến nghị cho CPU TDP tới 140 W; khả năng tản tối đa 200 W Kích thước/Trọng lượng: 123 x 96 x 130 mm (D x R x C), 700 g Keo tản nhiệt: Bôi sẵn ARCTIC MX-4 Bảo hành: 6 năm (giới hạn) | H13: 450000 | I13: Đã xác minh | J13: 46321 | K13: Lưu ý: mô tả trong kho ghi "4 ống đồng" chưa chắc đã sai. Bản Freezer 13 đầu tiên (2010) có 4 ống chữ U Ø6 mm, còn bảng thông số hiện hành (r6) ghi 3 ống. Ảnh sản phẩm chụp máy đời khoảng 2010-2012 (mainboard AMD in "Support 8-Core", tem 2009/2010) và không đếm rõ được số đầu ống. Cần xem hàng thực tế để chọn 3 hay 4 ống. | L13: https://arctic.de/media/fe/5f/d1/1584104671/spec_sheet_Freezer_13_180302_r6_EN.pdf

Sheet Màn hình
A1: Thông số kỹ thuật — Màn hình
A2: Đơn giá tham khảo là số liệu minh hoạ; thông số đã kiểm chứng ngày 26/10/2026, nguồn ở cột cuối.
A4: STT | B4: SKU | C4: Tên sản phẩm (trong kho) | D4: Model xác định | E4: Mô tả | F4: Kích thước | G4: Độ phân giải | H4: Tần số quét | I4: Tấm nền | J4: Độ cong | K4: Thời gian phản hồi | L4: Độ sáng/Tương phản | M4: HDR/Đồng bộ | N4: Cổng vào | O4: Loa | P4: VESA | Q4: Góc nhìn | R4: Năm ra mắt | S4: Đơn giá tham khảo (VND) | T4: Mức xác minh | U4: Ngày kiểm chứng | V4: Ghi chú | W4: Nguồn
A5: 1 | B5: MON-BENQ-CURVEDGAMING | C5: Màn hình Gaming cong BenQ | D5: BenQ MOBIUZ EX3210R (31,5", 1000R, 165 Hz) | E5: Màn hình gaming cong BenQ MOBIUZ 31,5 inch, độ cong 1000R, độ phân giải QHD 2560x1440, tần số quét 165 Hz. Tấm nền VA, hỗ trợ HDR400 và FreeSync Premium Pro, có loa 2.1 tích hợp. | F5: 31,5 inch | G5: 2560x1440 (QHD), 92 PPI | H5: 165 Hz | I5: VA, chống chói | J5: 1000R | K5: 1 ms (MPRT) | L5: 300 nit (400 nit đỉnh HDR), tương phản 2500:1 | M5: VESA DisplayHDR 400, HDR10; AMD FreeSync Premium Pro | N5: 2x HDMI 2.0, 1x DisplayPort 1.4, USB hub (1 up / 2x USB 3.0 down), jack tai nghe | O5: 2.1 kênh (2x 2 W + woofer 5 W) | P5: 100x100 (đơn vị: mm) | Q5: — | R5: — | S5: 7900000 | T5: Cấu hình tham khảo | U5: 46321 | V5: Giả định model: Dữ liệu kho không ghi model. Ảnh chụp gian hàng BenQ (chữ "Sim Racing-Monitore") với 3 màn cong 16:9 khoảng 32 inch. EX3210R là màn cong 16:9 gaming 32 inch phổ biến nhất của BenQ thời điểm đó. Không xác nhận được từ ảnh. Cấu hình tham khảo — chưa xác nhận đúng model của hàng trong kho. Chưa tìm thấy nguồn: Thời gian phản hồi GtG (BenQ chỉ ghi MPRT); Ngày ra mắt chính thức (đã có review năm 2021: https://www.tomshardware.com/reviews/benq-mobius-ex3210r-review) | W5: https://www.benq.com/en-ph/monitor/gaming/ex3210r/spec.html
A6: 2 | B6: MON-SAMSUNG-SYNCMASTER940B | C6: Màn hình Samsung SyncMaster 940B | D6: Samsung SyncMaster 940B (mã LS19HABTSQ theo Icecat) | E6: Màn hình LCD văn phòng Samsung SyncMaster 19 inch tỉ lệ 5:4, độ phân giải 1280x1024, tấm nền TN. Có cả cổng VGA (D-Sub) và DVI-D. | F6: 19 (48,3 cm), tỉ lệ 5:4 (đơn vị: inch) | G6: 1280x1024 | H6: 60 (tần số khuyến nghị ở 1280x1024; datasheet Samsung không ghi tần số tối đa) (đơn vị: Hz) | I6: TN | J6: Phẳng | K6: 8 (theo datasheet Samsung; một số listing bên thứ ba ghi 5 ms) | L6: 300 cd/m², tương phản 700:1 | M6: — | N6: D-Sub (VGA), DVI-D | O6: — | P6: — | Q6: 160° / 160° | R6: 2005 (datasheet Samsung ghi © 2005) | S6: 1990000 | T6: Đã xác minh | U6: 46321 | V6: Chưa tìm thấy nguồn: Tần số quét tối đa (datasheet không ghi; có người dùng báo chạy được 75 Hz) | W6: https://icecat.ro/p/samsung/ls19habtsq/computer+monitors-syncmaster+940b-328228.html https://images10.newegg.com/UploadFilesForNewegg/itemintelligence/Samsung/24-001-066/940b-black-ds.pdf https://www.lcd-compare.com/moniteur-SAMSM940B-SAMSUNG-SyncMaster-940B.htm

Sheet Phụ kiện
A1: Thông số kỹ thuật — Phụ kiện
A2: Đơn giá tham khảo là số liệu minh hoạ; thông số đã kiểm chứng ngày 26/10/2026, nguồn ở cột cuối.
A4: STT | B4: SKU | C4: Tên sản phẩm (trong kho) | D4: Model xác định | E4: Mô tả | F4: Thông số chính | G4: Đơn giá tham khảo (VND) | H4: Mức xác minh | I4: Ngày kiểm chứng | J4: Ghi chú | K4: Nguồn
A5: 1 | B5: KB-KEYCHRON-K4 | C5: Bàn phím cơ Keychron K4 | D5: Keychron K4 Wireless Mechanical Keyboard (Version 2, RGB, ANSI) | E5: Bàn phím cơ không dây Keychron K4 bố cục 96% (100 phím, có cụm phím số), kết nối Bluetooth 5.1 với tối đa 3 thiết bị hoặc dùng dây USB-C. Đèn nền RGB, pin 4000 mAh, tương thích macOS và Windows. | F5: Bố cục: 96%, 100 phím, ANSI (US), có cụm phím số Switch: Gateron Red / Blue / Brown (có bản hot-swap) Kết nối: Bluetooth 5.1 (tối đa 3 thiết bị) + có dây USB Type-C Pin: 4000 mAh; tới 240 giờ khi tắt đèn, khoảng 72 giờ khi bật RGB; sạc khoảng 3 giờ Đèn nền: RGB (có bản đèn trắng), 4 mức sáng Hệ điều hành hỗ trợ: macOS, Windows, iOS, Android Kích thước/Trọng lượng: Khung nhựa 371 x 124 x 38 mm, khoảng 770 g; khung nhôm 376 x 129 x 38 mm, khoảng 933 g | G5: 1890000 | H5: Đã đối chiếu — model suy luận | I5: 46321 | J5: Giả định model: Dữ liệu kho không ghi phiên bản. K4 có các bản V1, V2, V3 và K4 Pro. Chọn Version 2 (Bluetooth 5.1, bản RGB) vì là bản phổ biến nhất, khớp mô tả "96%, RGB, Bluetooth". Chưa tìm thấy nguồn: Polling rate (trang hãng không ghi) | K5: https://keychron.be/products/keychron-k4-wireless-mechanical-keyboard-version-2
A6: 2 | B6: MOUSE-PROTOARC-WIRELESS | C6: Chuột không dây ProtoArc | D6: ProtoArc EM15 Compact Portable Wireless Mouse (Black) | E6: Chuột không dây công thái học ProtoArc EM15 nặng 68 g, con lăn màu cam, kết nối Bluetooth và đầu thu USB-A/USB-C, chuyển nhanh giữa 3 thiết bị. Pin sạc qua cổng Type-C, nút trái phải bấm êm. | F6: dpi: 1000 / 1600 / 2400 (3 mức) (đơn vị: DPI) Kết nối: Bluetooth (BLE) + đầu thu không dây USB-A và USB-C (kèm theo); tối đa 3 thiết bị; tầm 10 m Nút bấm: Trái, phải, con lăn, DPI, nút chuyển thiết bị, 2 nút bên (tiến/lùi); nút trái phải bấm êm Pin: Li-Po sạc 300 mAh; dùng khoảng 15 ngày, chờ 200 ngày sau 2 giờ sạc; sạc qua Type-C Trọng lượng/Kích thước: 68 g; 125,4 x 64,6 x 39,3 mm Hệ điều hành hỗ trợ: Windows, macOS 10.10 trở lên, Android, ChromeOS (Bluetooth cần Windows 8+, macOS 10.10+, Android 4.3+) Đối chiếu màu: Bản đen có con lăn màu cam | G6: 450000 | H6: Đã đối chiếu — model suy luận | I6: 46321 | J6: Giả định model: Dữ liệu kho chỉ ghi "chuột không dây ProtoArc, công thái học". Ảnh là chuột ngang màu đen, con lăn màu cam, nút DPI và 2 nút bên. ProtoArc mô tả EM15 màu đen là "Black EM15 USB C wireless mouse with orange scroll wheel", khớp nhất với ảnh. Các model còn lại (EM11, EM05, EM03...) là chuột đứng hoặc trackball. Chưa tìm thấy nguồn: Phiên bản Bluetooth; Loại cảm biến | K6: https://www.protoarc.com/products/em15-usb-c-wireless-mouse https://www.protoarc.com/collections/portable-mice
A7: 3 | B7: HEADSET-CREATIVE-SBX-H5 | C7: Tai nghe Creative Sound BlasterX H5 | D7: Creative Sound BlasterX H5 (bản tiêu chuẩn, analog 3,5 mm) | E7: Tai nghe gaming chụp tai Creative Sound BlasterX H5 dùng driver 50 mm, kết nối jack 3,5 mm 4 cực, micro tháo rời có lọc ồn. Dùng được với PC, console và điện thoại. | F7: Driver loa: 50 mm neodymium (FullSpectrum), 20 Hz-20 kHz, 32 Ω, 118 dB/mW Kết nối: Có dây jack 3,5 mm 4 cực, cáp bện 1,2 m có điều khiển; kèm cáp chia tai nghe/mic Micro: Condenser một hướng, lọc ồn, tháo rời được; 100 Hz-15 kHz, -40 dB | G7: 1450000 | H7: Đã đối chiếu — model suy luận | I7: 46321 | J7: Giả định model: Ảnh đúng là Sound BlasterX H5 (logo BlasterX, chữ X đỏ, càng kim loại bạc). Bản Tournament Edition (TE) có driver và micro nâng cấp, mặt ốp tai bằng kim loại xước màu gun-metal. Ảnh có mặt ốp đen in hoạ tiết chấm, khớp bản tiêu chuẩn, và tên trong kho không có chữ "Tournament/TE". Chưa tìm thấy nguồn: Trọng lượng; Năm ra mắt; Trang Creative Asia trả 404 khi truy cập trực tiếp; số liệu lấy qua kết quả tìm kiếm trỏ tới trang này | K7: https://asia.creative.com/p/gaming-headsets/sound-blasterx-h5

Sheet Chi tiết thông số
A1: Chi tiết thông số theo từng giá trị
A2: Mỗi dòng một thông số; nguồn chính và nguồn đối chiếu ghi riêng.
A4: STT | B4: SKU | C4: Danh mục | D4: Model xác định | E4: Thuộc tính | F4: Giá trị | G4: Đơn vị | H4: Nguồn chính | I4: Nguồn đối chiếu | J4: Ghi chú nguồn
A5: 1 | B5: LAP-DELL-XPSM1330 | C5: Laptop | D5: Dell XPS M1330 (13.3", 2007-2008) | E5: CPU | F5: Intel Core 2 Duo, tuỳ cấu hình (vd. T7300 2.0 GHz; bản Penryn 2008: T9300 2.5 GHz) | H5: https://www.notebookcheck.net/Dell-XPS-M1330.5463.0.html | J5: T9300 theo https://www.laptopmag.com/reviews/laptops/dell-xps-m1330-penryn
A6: 2 | B6: LAP-DELL-XPSM1330 | C6: Laptop | D6: Dell XPS M1330 (13.3", 2007-2008) | E6: Chipset | F6: Intel PM965 (Crestline) + ICH8M | H6: https://www.notebookcheck.net/Dell-XPS-M1330.5463.0.html
A7: 3 | B7: LAP-DELL-XPSM1330 | C7: Laptop | D7: Dell XPS M1330 (13.3", 2007-2008) | E7: RAM | F7: 1-2 GB DDR2-667 (tuỳ cấu hình), tối đa 4 GB | G7: GB | H7: https://www.laptopmag.com/reviews/laptops/dell-xps-m1330-penryn | I7: https://www.notebookcheck.net/Dell-XPS-M1330.5463.0.html | J7: Notebookcheck: 1 GB (2x512 MB) DDR2-667
A8: 4 | B8: LAP-DELL-XPSM1330 | C8: Laptop | D8: Dell XPS M1330 (13.3", 2007-2008) | E8: Lưu trữ | F8: HDD SATA 5400 rpm, 120-160 GB tuỳ cấu hình | G8: GB | H8: https://www.notebookcheck.net/Dell-XPS-M1330.5463.0.html | J8: 160 GB theo https://www.laptopmag.com/reviews/laptops/dell-xps-m1330-penryn
A9: 5 | B9: LAP-DELL-XPSM1330 | C9: Laptop | D9: Dell XPS M1330 (13.3", 2007-2008) | E9: Màn hình | F9: 13,3 inch, 1280x800 (16:10), có tuỳ chọn đèn nền LED | G9: inch | H9: https://www.notebookcheck.net/Dell-XPS-M1330.5463.0.html
A10: 6 | B10: LAP-DELL-XPSM1330 | C10: Laptop | D10: Dell XPS M1330 (13.3", 2007-2008) | E10: Đồ hoạ (GPU) | F10: NVIDIA GeForce 8400M GS 128 MB | H10: https://www.notebookcheck.net/Dell-XPS-M1330.5463.0.html
A11: 7 | B11: LAP-DELL-XPSM1330 | C11: Laptop | D11: Dell XPS M1330 (13.3", 2007-2008) | E11: Trọng lượng | F11: khoảng 1,8 (pin 6 cell); khoảng 2,0 (4,5 lb) với pin 9 cell | G11: kg | H11: https://www.notebookcheck.net/Dell-XPS-M1330.5463.0.html | J11: 4,5 lb theo https://www.laptopmag.com/reviews/laptops/dell-xps-m1330-penryn
A12: 8 | B12: LAP-DELL-XPSM1330 | C12: Laptop | D12: Dell XPS M1330 (13.3", 2007-2008) | E12: Pin | F12: Li-ion 6 cell 56 Wh; tuỳ chọn pin 9 cell | G12: Wh | H12: https://www.notebookcheck.net/Dell-XPS-M1330.5463.0.html
A13: 9 | B13: LAP-DELL-XPSM1330 | C13: Laptop | D13: Dell XPS M1330 (13.3", 2007-2008) | E13: Cổng kết nối | F13: 2x USB 2.0, HDMI, VGA, FireWire, S-Video, LAN, modem, ExpressCard, mic, 2x tai nghe, khoá Kensington | H13: https://www.notebookcheck.net/Dell-XPS-M1330.5463.0.html
A14: 10 | B14: LAP-DELL-XPSM1330 | C14: Laptop | D14: Dell XPS M1330 (13.3", 2007-2008) | E14: Ổ quang | F14: DVD±RW dạng khe (slot-loading) | H14: https://www.notebookcheck.net/Dell-XPS-M1330.5463.0.html
A15: 11 | B15: LAP-DELL-XPSM1330 | C15: Laptop | D15: Dell XPS M1330 (13.3", 2007-2008) | E15: Hệ điều hành khi ra mắt | F15: Windows Vista Home Premium | H15: https://www.laptopmag.com/reviews/laptops/dell-xps-m1330-penryn
A16: 12 | B16: LAP-DELL-XPSM1330 | C16: Laptop | D16: Dell XPS M1330 (13.3", 2007-2008) | E16: Năm ra mắt | F16: 2007 (ra mắt 26/06/2007) | H16: https://www.notebookcheck.net/Dell-XPS-M1330.5463.0.html
A17: 13 | B17: LAP-LENOVO-T460 | C17: Laptop | D17: Lenovo ThinkPad T460 (2016, Intel Core thế hệ 6) | E17: CPU | F17: Intel Core i3-6100U / i5-6200U / i5-6300U / i7-6500U / i7-6600U (2 nhân 4 luồng) | H17: https://psref.lenovo.com/syspool/Sys/PDF/ThinkPad/ThinkPad_T460/ThinkPad_T460_Spec.PDF
A18: 14 | B18: LAP-LENOVO-T460 | C18: Laptop | D18: Lenovo ThinkPad T460 (2016, Intel Core thế hệ 6) | E18: RAM | F18: Tối đa 32 GB DDR3L-1600, 2 khe SO-DIMM, dual-channel | G18: GB | H18: https://psref.lenovo.com/syspool/Sys/PDF/ThinkPad/ThinkPad_T460/ThinkPad_T460_Spec.PDF
A19: 15 | B19: LAP-LENOVO-T460 | C19: Laptop | D19: Lenovo ThinkPad T460 (2016, Intel Core thế hệ 6) | E19: Lưu trữ | F19: SSD SATA, SSD PCIe NVMe (PCIe 3.0 x2), HDD 2,5" hoặc SSHD (tuỳ cấu hình) | H19: https://psref.lenovo.com/syspool/Sys/PDF/ThinkPad/ThinkPad_T460/ThinkPad_T460_Spec.PDF
A20: 16 | B20: LAP-LENOVO-T460 | C20: Laptop | D20: Lenovo ThinkPad T460 (2016, Intel Core thế hệ 6) | E20: Màn hình | F20: 14 inch HD 1366x768 TN hoặc FHD 1920x1080 IPS; tuỳ chọn cảm ứng | G20: inch | H20: https://psref.lenovo.com/syspool/Sys/PDF/ThinkPad/ThinkPad_T460/ThinkPad_T460_Spec.PDF | J20: PSREF không ghi loại tấm nền của bản HD (chỉ ghi 200 nit, 350:1), nên "TN" chưa có nguồn thứ hai
A21: 17 | B21: LAP-LENOVO-T460 | C21: Laptop | D21: Lenovo ThinkPad T460 (2016, Intel Core thế hệ 6) | E21: Đồ hoạ (GPU) | F21: Intel HD Graphics 520; tuỳ chọn NVIDIA GeForce 940MX 2 GB | H21: https://psref.lenovo.com/syspool/Sys/PDF/ThinkPad/ThinkPad_T460/ThinkPad_T460_Spec.PDF | J21: PSREF: GPU rời 940MX chỉ bán ở thị trường Mỹ; i7-6500U chỉ có trên bản có GPU rời
A22: 18 | B22: LAP-LENOVO-T460 | C22: Laptop | D22: Lenovo ThinkPad T460 (2016, Intel Core thế hệ 6) | E22: Trọng lượng | F22: từ 1,73 (3+3 cell, không cảm ứng) | G22: kg | H22: https://psref.lenovo.com/syspool/Sys/PDF/ThinkPad/ThinkPad_T460/ThinkPad_T460_Spec.PDF
A23: 19 | B23: LAP-LENOVO-T460 | C23: Laptop | D23: Lenovo ThinkPad T460 (2016, Intel Core thế hệ 6) | E23: Pin | F23: Pin trong 3 cell 23 Wh (tuỳ cấu hình, có bản không có pin trong) + pin ngoài 3 cell 23 Wh hoặc 6 cell 48/72 Wh (Power Bridge) | G23: Wh | H23: https://psref.lenovo.com/syspool/Sys/PDF/ThinkPad/ThinkPad_T460/ThinkPad_T460_Spec.PDF
A24: 20 | B24: LAP-LENOVO-T460 | C24: Laptop | D24: Lenovo ThinkPad T460 (2016, Intel Core thế hệ 6) | E24: Cổng kết nối | F24: 3x USB 3.0, HDMI, Mini DisplayPort, RJ-45, cổng dock, đầu đọc thẻ 4-in-1, jack âm thanh combo; tuỳ chọn smart card | H24: https://psref.lenovo.com/syspool/Sys/PDF/ThinkPad/ThinkPad_T460/ThinkPad_T460_Spec.PDF
A25: 21 | B25: LAP-LENOVO-T460 | C25: Laptop | D25: Lenovo ThinkPad T460 (2016, Intel Core thế hệ 6) | E25: Hệ điều hành khi ra mắt | F25: Windows 10 Pro 64-bit hoặc Windows 7 Pro (hạ cấp từ Windows 10 Pro) | H25: https://psref.lenovo.com/syspool/Sys/PDF/ThinkPad/ThinkPad_T460/ThinkPad_T460_Spec.PDF
A26: 22 | B26: LAP-LENOVO-T460 | C26: Laptop | D26: Lenovo ThinkPad T460 (2016, Intel Core thế hệ 6) | E26: Năm ra mắt | F26: 2016 (công bố tại CES tháng 1/2016) | H26: https://pcper.com/2016/01/ces-2016-lenovo-announces-thinkpad-t460-series-notebooks/
A27: 23 | B27: LAP-HP-ENVY14 | C27: Laptop | D27: HP ENVY Laptop 14-eb0021TX (Core i7-1165G7, GTX 1650 Ti Max-Q) | E27: CPU | F27: Intel Core i7-1165G7, 4 nhân 8 luồng, 2,8-4,7 GHz | G27: GHz | H27: https://www.notebookcheck.net/HP-Envy-14-eb0021tx.602559.0.html | I27: https://globallinker.com/products/hp-envy-14-eb0021tx-silver-11th-gen-i7-1165g7-16gb-1-tb-ssd-14-16-10-aspect-ratio-wuxga-antiglare-ips-400-nits-low-power-narrow-border-flat-4gb-nvidia-geforce-gtx-1650ti-windows-10-home-s-2019-backlit-keyboard-fpr-7198181
A28: 24 | B28: LAP-HP-ENVY14 | C28: Laptop | D28: HP ENVY Laptop 14-eb0021TX (Core i7-1165G7, GTX 1650 Ti Max-Q) | E28: RAM | F28: 16 GB DDR4-3200 | G28: GB | H28: https://www.notebookcheck.net/HP-Envy-14-eb0021tx.602559.0.html | I28: https://globallinker.com/products/hp-envy-14-eb0021tx-silver-11th-gen-i7-1165g7-16gb-1-tb-ssd-14-16-10-aspect-ratio-wuxga-antiglare-ips-400-nits-low-power-narrow-border-flat-4gb-nvidia-geforce-gtx-1650ti-windows-10-home-s-2019-backlit-keyboard-fpr-7198181
A29: 25 | B29: LAP-HP-ENVY14 | C29: Laptop | D29: HP ENVY Laptop 14-eb0021TX (Core i7-1165G7, GTX 1650 Ti Max-Q) | E29: Lưu trữ | F29: SSD PCIe NVMe 1 TB | G29: TB | H29: https://www.notebookcheck.net/HP-Envy-14-eb0021tx.602559.0.html | I29: https://globallinker.com/products/hp-envy-14-eb0021tx-silver-11th-gen-i7-1165g7-16gb-1-tb-ssd-14-16-10-aspect-ratio-wuxga-antiglare-ips-400-nits-low-power-narrow-border-flat-4gb-nvidia-geforce-gtx-1650ti-windows-10-home-s-2019-backlit-keyboard-fpr-7198181
A30: 26 | B30: LAP-HP-ENVY14 | C30: Laptop | D30: HP ENVY Laptop 14-eb0021TX (Core i7-1165G7, GTX 1650 Ti Max-Q) | E30: Màn hình | F30: 14 inch IPS 1920x1200 (16:10), 60 Hz | G30: inch | H30: https://www.notebookcheck.net/HP-Envy-14-eb0021tx.602559.0.html | I30: https://globallinker.com/products/hp-envy-14-eb0021tx-silver-11th-gen-i7-1165g7-16gb-1-tb-ssd-14-16-10-aspect-ratio-wuxga-antiglare-ips-400-nits-low-power-narrow-border-flat-4gb-nvidia-geforce-gtx-1650ti-windows-10-home-s-2019-backlit-keyboard-fpr-7198181 | J30: 16:10 theo windowscentral và listing bán lẻ theo SKU (WUXGA, IPS, 400 nit, chống chói). Bảng của Notebookcheck ghi nhầm 16:9
A31: 27 | B31: LAP-HP-ENVY14 | C31: Laptop | D31: HP ENVY Laptop 14-eb0021TX (Core i7-1165G7, GTX 1650 Ti Max-Q) | E31: Đồ hoạ (GPU) | F31: NVIDIA GeForce GTX 1650 Ti Max-Q 4 GB GDDR6 + Intel Iris Xe | H31: https://www.notebookcheck.net/HP-Envy-14-eb0021tx.602559.0.html | I31: https://globallinker.com/products/hp-envy-14-eb0021tx-silver-11th-gen-i7-1165g7-16gb-1-tb-ssd-14-16-10-aspect-ratio-wuxga-antiglare-ips-400-nits-low-power-narrow-border-flat-4gb-nvidia-geforce-gtx-1650ti-windows-10-home-s-2019-backlit-keyboard-fpr-7198181
A32: 28 | B32: LAP-HP-ENVY14 | C32: Laptop | D32: HP ENVY Laptop 14-eb0021TX (Core i7-1165G7, GTX 1650 Ti Max-Q) | E32: Trọng lượng | F32: 1,49 | G32: kg | H32: https://www.notebookcheck.net/HP-Envy-14-eb0021tx.602559.0.html
A33: 29 | B33: LAP-HP-ENVY14 | C33: Laptop | D33: HP ENVY Laptop 14-eb0021TX (Core i7-1165G7, GTX 1650 Ti Max-Q) | E33: Pin | F33: 63,3 Wh, 4 cell Li-Po | G33: Wh | H33: https://www.notebookcheck.net/HP-Envy-14-eb0021tx.602559.0.html
A34: 30 | B34: LAP-HP-ENVY14 | C34: Laptop | D34: HP ENVY Laptop 14-eb0021TX (Core i7-1165G7, GTX 1650 Ti Max-Q) | E34: Cổng kết nối | F34: 2x USB-A 5 Gbps, 1x Thunderbolt (USB-C), HDMI, jack 3,5 mm, khe microSD | H34: https://www.notebookcheck.net/HP-Envy-14-eb0021tx.602559.0.html
A35: 31 | B35: LAP-HP-ENVY14 | C35: Laptop | D35: HP ENVY Laptop 14-eb0021TX (Core i7-1165G7, GTX 1650 Ti Max-Q) | E35: Hệ điều hành khi ra mắt | F35: Windows 10 Home 64-bit | H35: https://www.notebookcheck.net/HP-Envy-14-eb0021tx.602559.0.html
A36: 32 | B36: LAP-HP-ENVY14 | C36: Laptop | D36: HP ENVY Laptop 14-eb0021TX (Core i7-1165G7, GTX 1650 Ti Max-Q) | E36: Năm ra mắt | F36: 2021 (công bố tại CES tháng 1/2021, giá từ 999 USD) | H36: https://windowscentral.com/hp-unveils-new-envy-14-intel-11th-gen-chips-and-dedicated-nvidia-gtx-1650-graphics
A37: 33 | B37: PC-GAMING-FRACTAL-TUF | C37: PC để bàn | D37: PC gaming lắp ráp: vỏ Fractal Design Focus G (Petrol Blue) với linh kiện ASUS TUF Gaming | E37: Kiểu dáng | F37: Vỏ ATX Mid Tower (hỗ trợ ATX / Micro-ATX / Mini-ITX), 7 khe mở rộng | H37: https://www.fractal-design.com/products/cases/focus/focus-g/white/ | J37: màu Petrol Blue theo https://www.walmart.com/ip/338891926
A38: 34 | B38: PC-GAMING-FRACTAL-TUF | C38: PC để bàn | D38: PC gaming lắp ráp: vỏ Fractal Design Focus G (Petrol Blue) với linh kiện ASUS TUF Gaming | E38: Tuỳ chọn CPU | F38: AMD Ryzen socket AM4 (nhìn thấy tản AMD Wraith Prism; chưa xác định model CPU) | H38: Ảnh sản phẩm trong kho (pc-gaming-fractal-tuf.webp): nhãn, tem nhìn thấy trên ảnh | I38: ảnh sản phẩm trong kho (đã xem lại: tản AMD Wraith Prism có viền RGB; VGA ghi GEFORCE GTX / CERBERUS)
A39: 35 | B39: PC-GAMING-FRACTAL-TUF | C39: PC để bàn | D39: PC gaming lắp ráp: vỏ Fractal Design Focus G (Petrol Blue) với linh kiện ASUS TUF Gaming | E39: Đồ hoạ (GPU) | F39: ASUS Cerberus GeForce GTX (model cụ thể chưa xác định) | H39: Ảnh sản phẩm trong kho (pc-gaming-fractal-tuf.webp): nhãn, tem nhìn thấy trên ảnh | I39: ảnh sản phẩm trong kho (đã xem lại: tản AMD Wraith Prism có viền RGB; VGA ghi GEFORCE GTX / CERBERUS)
A40: 36 | B40: PC-GAMING-FRACTAL-TUF | C40: PC để bàn | D40: PC gaming lắp ráp: vỏ Fractal Design Focus G (Petrol Blue) với linh kiện ASUS TUF Gaming | E40: Lưu trữ | F40: Vỏ có 2x 5.25", 2x 3,5"/2,5", 1x 2,5" chuyên dụng (ảnh: 1 HDD 3,5" + 1 SSD 2,5") | H40: https://www.fractal-design.com/products/cases/focus/focus-g/white/
A41: 37 | B41: PC-GAMING-FRACTAL-TUF | C41: PC để bàn | D41: PC gaming lắp ráp: vỏ Fractal Design Focus G (Petrol Blue) với linh kiện ASUS TUF Gaming | E41: Cổng mặt trước | F41: 1x USB 2.0, 1x USB-A 5 Gbps, jack tai nghe, jack mic | H41: https://www.fractal-design.com/products/cases/focus/focus-g/white/
...
